<robot name="dexhand021_right">

  <mujoco>
    <compiler meshdir="../meshes/dexhand021" balanceinertia="true" discardvisual="false" />
  </mujoco>

  <link name="right_hand_base" />

  <joint name="right_base_to_hand" type="fixed">
    <parent link="right_hand_base" />
    <child link="r_p_link0" />
    <origin xyz="0. 0. -0.17" rpy="0 0 -1.57" />
  </joint>

  <link name="r_p_link0">
    <inertial>
      <origin xyz="0.0011074986817912846 0.006472387526997947 0.23409601570168226" rpy="0 0 0" />
      <mass value="0.4581543554912673" />
      <inertia ixx="1.0350833665771442e-07" ixy="-8.319054634221741e-10" ixz="5.221502157999468e-09" iyy="1.297257523689786e-07" iyz="-1.4385510644191774e-08" izz="4.272589354090268e-08" />
    </inertial>
    <visual>
      <origin xyz="0 0 0" rpy="0 0 0" />
      <geometry>
        <mesh filename="../meshes/dexhand021/r_p_link0.STL" />
      </geometry>
      <material name="">
        <color rgba="0.3 0.3 0.3 1" />
      </material>
    </visual>
    <collision>
      <origin xyz="0 0 0" rpy="0 0 0" />
      <geometry>
        <mesh filename="../meshes/dexhand021/r_p_link0.STL" />
      </geometry>
    </collision>
  </link>

  <link name="r_f_link1_1">
    <inertial>
      <origin xyz="0.002052234636018281 -0.00037264296027423964 -0.018528755499499953" rpy="0 0 0" />
      <mass value="0.005180345914026771" />
      <inertia ixx="1.1430624890840812e-09" ixy="5.518285795047138e-12" ixz="-1.0163028770836786e-10" iyy="1.2177661234390167e-09" iyz="3.027326337843877e-11" izz="2.6375976308253895e-10" />
    </inertial>
    <visual>
      <origin xyz="0 0 0" rpy="0 0 0" />
      <geometry>
        <mesh filename="../meshes/dexhand021/r_f_link1_1.STL" />
      </geometry>
      <material name="">
        <color rgba="0.3 0.3 0.3 1" />
      </material>
    </visual>
    <collision>
      <origin xyz="0 0 0" rpy="0 0 0" />
      <geometry>
        <mesh filename="../meshes/dexhand021/r_f_link1_1.STL" />
      </geometry>
    </collision>
  </link>

  <joint name="r_f_joint1_1" type="revolute">
    <origin xyz="-0.023855 0.032704 0.27707" rpy="0.26842 -0.15197 2.8876" />
    <parent link="r_p_link0" />
    <child link="r_f_link1_1" />
    <axis xyz="0 0 -1" />
    <limit lower="0" upper="2.2" effort="10" velocity="1.5" />
    <joint_properties damping="0.3" friction="0.5" />
  </joint>

  <link name="r_f_link1_2">
    <inertial>
      <origin xyz="0.021535504665713034 -0.0005063776397706903 0.0008142325238396855" rpy="0 0 0" />
      <mass value="0.005145873046732899" />
      <inertia ixx="2.095562573407677e-10" ixy="9.153029438541743e-12" ixz="-1.1384864654098634e-13" iyy="1.0604069584701189e-09" iyz="-1.1306254380399874e-12" izz="1.0442073361852393e-09" />
    </inertial>
    <visual>
      <origin xyz="0 0 0" rpy="0 0 0" />
      <geometry>
        <mesh filename="../meshes/dexhand021/r_f_link1_2.STL" />
      </geometry>
      <material name="">
        <color rgba="0.3 0.3 0.3 1" />
      </material>
    </visual>
    <collision>
      <origin xyz="0 0 0" rpy="0 0 0" />
      <geometry>
        <mesh filename="../meshes/dexhand021/r_f_link1_2.STL" />
      </geometry>
    </collision>
  </link>

  <joint name="r_f_joint1_2" type="revolute">
    <origin xyz="0.0083307 0 0" rpy="1.5708 0.019099 0" />
    <parent link="r_f_link1_1" />
    <child link="r_f_link1_2" />
    <axis xyz="0 0 1" />
    <limit lower="0" upper="1.3" effort="10" velocity="1.5" />
    <joint_properties damping="0.3" friction="0.5" effort="10" velocity="1.5" />
  </joint>

  <link name="r_f_link1_3">
    <inertial>
      <origin xyz="0.013223206653743833 -0.0007239105528826962 0.0012977744957347582" rpy="0 0 0" />
      <mass value="0.003510129470234603" />
      <inertia ixx="1.0264326739890384e-10" ixy="1.00343840042598e-11" ixz="-1.537174856938822e-12" iyy="3.145228617298157e-10" iyz="-3.584871833385339e-14" izz="3.2605393609475025e-10" />
    </inertial>
    <visual>
      <origin xyz="0 0 0" rpy="0 0 0" />
      <geometry>
        <mesh filename="../meshes/dexhand021/r_f_link1_3.STL" />
      </geometry>
      <material name="">
        <color rgba="0.3 0.3 0.3 1" />
      </material>
    </visual>
    <collision>
      <origin xyz="0 0 0" rpy="0 0 0" />
      <geometry>
        <mesh filename="../meshes/dexhand021/r_f_link1_3.STL" />
      </geometry>
    </collision>
  </link>

  <joint name="r_f_joint1_3" type="revolute">
    <origin xyz="0.043 0 0" rpy="0 0 0" />
    <parent link="r_f_link1_2" />
    <child link="r_f_link1_3" />
    <axis xyz="0 0 1" />
    <limit lower="0" upper="1.3" effort="10" velocity="1.5" />
    <joint_properties damping="0.3" friction="0.5" effort="10" velocity="1.5" />
  </joint>

  <link name="r_f_link1_4">
    <inertial>
      <origin xyz="0.016827162662944168 -0.0025428441924313476 0.0012898514164979443" rpy="0 0 0" />
      <mass value="0.00435766768406691" />
      <inertia ixx="1.728886893578917e-10" ixy="7.193280509045395e-11" ixz="9.525487099852026e-14" iyy="5.47556480763753e-10" iyz="-4.665149094714642e-14" izz="5.333289131753526e-10" />
    </inertial>
    <visual>
      <origin xyz="0 0 0" rpy="0 0 0" />
      <geometry>
        <mesh filename="../meshes/dexhand021/r_f_link1_4.STL" />
      </geometry>
      <material name="">
        <color rgba="0.3 0.3 0.3 1" />
      </material>
    </visual>
    <collision>
      <origin xyz="0 0 0" rpy="0 0 0" />
      <geometry>
        <mesh filename="../meshes/dexhand021/r_f_link1_4.STL" />
      </geometry>
    </collision>
  </link>

  <joint name="r_f_joint1_4" type="revolute">
    <origin xyz="0.025 0 0" rpy="0 0 0" />
    <parent link="r_f_link1_3" />
    <child link="r_f_link1_4" />
    <axis xyz="0 0 1" />
    <limit lower="0" upper="1.3" effort="10" velocity="1.5" />
    <joint_properties damping="0.3" friction="0.5" effort="10" velocity="1.5" />
  </joint>

  <link name="r_f_link1_4_1">
    <inertial>
      <origin xyz="0.00976545037646227 0.006088691115452144 0.0012928496121529978" rpy="0 0 0" />
      <mass value="0.00037285923791626445" />
      <inertia ixx="1.0806913722591278e-11" ixy="-1.434355226187965e-13" ixz="7.904650389859608e-16" iyy="1.2799737603403855e-11" iyz="9.706804921696106e-17" izz="2.971985515053042e-12" />
    </inertial>
    <visual>
      <origin xyz="0 0 0" rpy="0 0 0" />
      <geometry>
        <mesh filename="../meshes/dexhand021/r_f_link1_4_1.STL" />
      </geometry>
      <material name="">
        <color rgba="0.3 0.3 0.3 1" />
      </material>
    </visual>
    <collision>
      <origin xyz="0 0 0" rpy="0 0 0" />
      <geometry>
        <mesh filename="../meshes/dexhand021/r_f_link1_4_1.STL" />
      </geometry>
    </collision>
  </link>
  <joint name="r_f_joint1_4_1" type="fixed">
    <origin xyz="0 0 0" rpy="0 0 0" />
    <parent link="r_f_link1_4" />
    <child link="r_f_link1_4_1" />
    <axis xyz="0 0 0" />
  </joint>

  <link name="r_f_link1_4_2">
    <inertial>
      <origin xyz="0.015433183995062187 -0.0061487266621455365 0.0012940973222927408" rpy="0 0 0" />
      <mass value="0.0019468120969125988" />
      <inertia ixx="1.4302400339154933e-10" ixy="4.887309828246755e-11" ixz="-5.685919419601672e-14" iyy="3.2625738627404405e-10" iyz="7.480451372260064e-15" izz="2.8666011578141624e-10" />
    </inertial>
    <visual>
      <origin xyz="0 0 0" rpy="0 0 0" />
      <geometry>
        <mesh filename="../meshes/dexhand021/r_f_link1_4_2.STL" />
      </geometry>
      <material name="">
        <color rgba="0.9 0.9 0.9 1" />
      </material>
    </visual>
    <collision>
      <origin xyz="0 0 0" rpy="0 0 0" />
      <geometry>
        <mesh filename="../meshes/dexhand021/r_f_link1_4_2.STL" />
      </geometry>
    </collision>
  </link>

  <joint name="r_f_joint1_4_2" type="fixed">
    <origin xyz="0 0 0" rpy="0 0 0" />
    <parent link="r_f_link1_4" />
    <child link="r_f_link1_4_2" />
    <axis xyz="0 0 0" />
  </joint>

  <link name="r_f_link1_3_1">
    <inertial>
      <origin xyz="0.012419626621348002 0.007723681641112162 0.0012920357276482693" rpy="0 0 0" />
      <mass value="0.0004927439497821333" />
      <inertia ixx="1.4812698827671588e-11" ixy="-2.4625303330183365e-13" ixz="-5.204752318762885e-16" iyy="1.688627032313685e-11" iyz="-7.055265282688354e-16" izz="4.840002879941831e-12" />
    </inertial>
    <visual>
      <origin xyz="0 0 0" rpy="0 0 0" />
      <geometry>
        <mesh filename="../meshes/dexhand021/r_f_link1_3_1.STL" />
      </geometry>
      <material name="">
        <color rgba="0.3 0.3 0.3 1" />
      </material>
    </visual>
    <collision>
      <origin xyz="0 0 0" rpy="0 0 0" />
      <geometry>
        <mesh filename="../meshes/dexhand021/r_f_link1_3_1.STL" />
      </geometry>
    </collision>
  </link>

  <joint name="r_f_joint1_3_1" type="fixed">
    <origin xyz="0 0 0" rpy="0 0 0" />
    <parent link="r_f_link1_3" />
    <child link="r_f_link1_3_1" />
    <axis xyz="0 0 0" />
  </joint>
  <link name="r_f_link1_3_2">
    <inertial>
      <origin xyz="0.012938038149695234 -0.004966116981932351 0.0012957151384533254" rpy="0 0 0" />
      <mass value="0.0009264867224319483" />
      <inertia ixx="5.342701293871887e-11" ixy="7.101425075294421e-13" ixz="-1.771926549530019e-15" iyy="7.062474289204522e-11" iyz="1.4720413014316507e-15" izz="4.7550430803969934e-11" />
    </inertial>
    <visual>
      <origin xyz="0 0 0" rpy="0 0 0" />
      <geometry>
        <mesh filename="../meshes/dexhand021/r_f_link1_3_2.STL" />
      </geometry>
      <material name="">
        <color rgba="0.9 0.9 0.9 1" />
      </material>
    </visual>
    <collision>
      <origin xyz="0 0 0" rpy="0 0 0" />
      <geometry>
        <mesh filename="../meshes/dexhand021/r_f_link1_3_2.STL" />
      </geometry>
    </collision>
  </link>

  <joint name="r_f_joint1_3_2" type="fixed">
    <origin xyz="0 0 0" rpy="0 0 0" />
    <parent link="r_f_link1_3" />
    <child link="r_f_link1_3_2" />
    <axis xyz="0 0 0" />
  </joint>

  <link name="r_f_link1_2_1">
    <inertial>
      <origin xyz="0.02043366719765508 0.0095110012352192 0.0012923408126127045" rpy="0 0 0" />
      <mass value="0.0016354719692142122" />
      <inertia ixx="4.406768580953342e-11" ixy="3.6957813554077775e-12" ixz="6.271444606736929e-15" iyy="9.649204412507137e-11" iyz="-3.0566463158202232e-15" izz="6.793850270146395e-11" />
    </inertial>
    <visual>
      <origin xyz="0 0 0" rpy="0 0 0" />
      <geometry>
        <mesh filename="../meshes/dexhand021/r_f_link1_2_1.STL" />
      </geometry>
      <material name="">
        <color rgba="0.3 0.3 0.3 1" />
      </material>
    </visual>
    <collision>
      <origin xyz="0 0 0" rpy="0 0 0" />
      <geometry>
        <mesh filename="../meshes/dexhand021/r_f_link1_2_1.STL" />
      </geometry>
    </collision>
  </link>

  <joint name="r_f_joint1_2_1" type="fixed">
    <origin xyz="0 0 0" rpy="0 0 0" />
    <parent link="r_f_link1_2" />
    <child link="r_f_link1_2_1" />
    <axis xyz="0 0 0" />
  </joint>

  <link name="r_f_link1_2_2">
    <inertial>
      <origin xyz="0.022921501261816545 -0.0027716306188103625 0.0012979021572152708" rpy="0 0 0" />
      <mass value="0.002536590997261413" />
      <inertia ixx="2.2859663761882352e-10" ixy="1.3411101520302956e-11" ixz="3.0992878304785846e-13" iyy="6.01449052592349e-10" iyz="9.341938224099394e-14" izz="5.304297061779193e-10" />
    </inertial>
    <visual>
      <origin xyz="0 0 0" rpy="0 0 0" />
      <geometry>
        <mesh filename="../meshes/dexhand021/r_f_link1_2_2.STL" />
      </geometry>
      <material name="">
        <color rgba="0.9 0.9 0.9 1" />
      </material>
    </visual>
    <collision>
      <origin xyz="0 0 0" rpy="0 0 0" />
      <geometry>
        <mesh filename="../meshes/dexhand021/r_f_link1_2_2.STL" />
      </geometry>
    </collision>
  </link>

  <joint name="r_f_joint1_2_2" type="fixed">
    <origin xyz="0 0 0" rpy="0 0 0" />
    <parent link="r_f_link1_2" />
    <child link="r_f_link1_2_2" />
    <axis xyz="0 0 0" />
  </joint>

  <link name="r_f_link2_1">
    <inertial>
      <origin xyz="0.00800686231185624 1.8338860572319307e-05 -0.0015842278080929802" rpy="0 0 0" />
      <mass value="0.0035185790867912825" />
      <inertia ixx="2.306699006679482e-10" ixy="-8.218728590128597e-13" ixz="4.890426965618435e-11" iyy="3.7198481717440744e-10" iyz="-1.5962544309162244e-13" izz="2.9800529687295447e-10" />
    </inertial>
    <visual>
      <origin xyz="0 0 0" rpy="0 0 0" />
      <geometry>
        <mesh filename="../meshes/dexhand021/r_f_link2_1.STL" />
      </geometry>
      <material name="">
        <color rgba="0.3 0.3 0.3 1" />
      </material>
    </visual>
    <collision>
      <origin xyz="0 0 0" rpy="0 0 0" />
      <geometry>
        <mesh filename="../meshes/dexhand021/r_f_link2_1.STL" />
      </geometry>
    </collision>
  </link>

  <joint name="r_f_joint2_1" type="revolute">
    <origin xyz="-0.034912 0.006966 0.3297" rpy="-1.5704 -1.5708 -0.00037051" />
    <parent link="r_p_link0" />
    <child link="r_f_link2_1" />
    <axis xyz="0 0 -1" />
    <limit lower="0" upper="0.6" effort="10" velocity="1.5" />
    <joint_properties damping="0.3" friction="0.5" />
  </joint>

  <link name="r_f_link2_2">
    <inertial>
      <origin xyz="0.021444679550905597 -0.00046289490893125946 -0.00047869270897582744" rpy="0 0 0" />
      <mass value="0.00498936744865468" />
      <inertia ixx="2.0644763911341986e-10" ixy="8.780455972495662e-12" ixz="-2.955798697672007e-13" iyy="1.0552014748309064e-09" iyz="-9.019287841475982e-13" izz="1.0401625323233909e-09" />
    </inertial>
    <visual>
      <origin xyz="0 0 0" rpy="0 0 0" />
      <geometry>
        <mesh filename="../meshes/dexhand021/r_f_link2_2.STL" />
      </geometry>
      <material name="">
        <color rgba="0.3 0.3 0.3 1" />
      </material>
    </visual>
    <collision>
      <origin xyz="0 0 0" rpy="0 0 0" />
      <geometry>
        <mesh filename="../meshes/dexhand021/r_f_link2_2.STL" />
      </geometry>
    </collision>
  </link>

  <joint name="r_f_joint2_2" type="revolute">
    <origin xyz="0.017 0 0" rpy="1.5708 0 0" />
    <parent link="r_f_link2_1" />
    <child link="r_f_link2_2" />
    <axis xyz="0 0 1" />
    <limit lower="0" upper="1.3" effort="10" velocity="1.5" />
    <joint_properties damping="0.3" friction="0.5" />
  </joint>

  <link name="r_f_link2_3">
    <inertial>
      <origin xyz="0.013280328692675957 -0.000619931592170148 -1.7863321659893763e-05" rpy="0 0 0" />
      <mass value="0.003320332898413509" />
      <inertia ixx="9.569221204956144e-11" ixy="1.0826362598444603e-11" ixz="-1.618171363270053e-12" iyy="3.077893159220674e-10" iyz="-8.827964273954513e-14" izz="3.2064040293000987e-10" />
    </inertial>
    <visual>
      <origin xyz="0 0 0" rpy="0 0 0" />
      <geometry>
        <mesh filename="../meshes/dexhand021/r_f_link2_3.STL" />
      </geometry>
      <material name="">
        <color rgba="0.3 0.3 0.3 1" />
      </material>
    </visual>
    <collision>
      <origin xyz="0 0 0" rpy="0 0 0" />
      <geometry>
        <mesh filename="../meshes/dexhand021/r_f_link2_3.STL" />
      </geometry>
    </collision>
  </link>

  <joint name="r_f_joint2_3" type="revolute">
    <origin xyz="0.043 0 0" rpy="0 0 0" />
    <parent link="r_f_link2_2" />
    <child link="r_f_link2_3" />
    <axis xyz="0 0 1" />
    <limit lower="0" upper="1.3" effort="10" velocity="1.5" />
    <joint_properties damping="0.3" friction="0.5" />
  </joint>

  <link name="r_f_link2_4">
    <inertial>
      <origin xyz="0.016835724143011772 -0.002545133894972038 -2.3757910612300705e-06" rpy="0 0 0" />
      <mass value="0.004352952819365211" />
      <inertia ixx="1.7269823391120783e-10" ixy="7.185121765683682e-11" ixz="1.0129621345450238e-13" iyy="5.47093812720547e-10" iyz="-4.584119052051053e-14" izz="5.330028957299744e-10" />
    </inertial>
    <visual>
      <origin xyz="0 0 0" rpy="0 0 0" />
      <geometry>
        <mesh filename="../meshes/dexhand021/r_f_link2_4.STL" />
      </geometry>
      <material name="">
        <color rgba="0.3 0.3 0.3 1" />
      </material>
    </visual>
    <collision>
      <origin xyz="0 0 0" rpy="0 0 0" />
      <geometry>
        <mesh filename="../meshes/dexhand021/r_f_link2_4.STL" />
      </geometry>
    </collision>
  </link>

  <joint name="r_f_joint2_4" type="revolute">
    <origin xyz="0.025 0 0" rpy="0 0 0" />
    <parent link="r_f_link2_3" />
    <child link="r_f_link2_4" />
    <axis xyz="0 0 1" />
    <limit lower="0" upper="1.3" effort="10" velocity="1.5" />
    <joint_properties damping="0.3" friction="0.5" />
  </joint>

  <link name="r_f_link2_4_1">
    <inertial>
      <origin xyz="0.009738422454577171 0.005930029867600307 5.184462774280181e-07" rpy="0 0 0" />
      <mass value="0.00038943301930674843" />
      <inertia ixx="1.1761888707665848e-11" ixy="-1.9209378389905702e-13" ixz="1.1862850720139697e-15" iyy="1.3432121472297152e-11" iyz="1.5284550933443108e-16" izz="3.328060571268917e-12" />
    </inertial>
    <visual>
      <origin xyz="0 0 0" rpy="0 0 0" />
      <geometry>
        <mesh filename="../meshes/dexhand021/r_f_link2_4_1.STL" />
      </geometry>
      <material name="">
        <color rgba="0.3 0.3 0.3 1" />
      </material>
    </visual>
    <collision>
      <origin xyz="0 0 0" rpy="0 0 0" />
      <geometry>
        <mesh filename="../meshes/dexhand021/r_f_link2_4_1.STL" />
      </geometry>
    </collision>
  </link>

  <joint name="r_f_joint2_4_1" type="fixed">
    <origin xyz="0 0 0" rpy="0 0 0" />
    <parent link="r_f_link2_4" />
    <child link="r_f_link2_4_1" />
    <axis xyz="0 0 0" />
  </joint>

  <link name="r_f_link2_4_2">
    <inertial>
      <origin xyz="0.015433183876606105 -0.0061487266132256285 1.6634835699823495e-06" rpy="0 0 0" />
      <mass value="0.0019468121675446145" />
      <inertia ixx="1.4302405503412767e-10" ixy="4.8873098825622075e-11" ixz="-5.680610977824491e-14" iyy="3.2625743956843556e-10" iyz="7.694530504406818e-15" izz="2.8666011857758843e-10" />
    </inertial>
    <visual>
      <origin xyz="0 0 0" rpy="0 0 0" />
      <geometry>
        <mesh filename="../meshes/dexhand021/r_f_link2_4_2.STL" />
      </geometry>
      <material name="">
        <color rgba="0.9 0.9 0.9 1" />
      </material>
    </visual>
    <collision>
      <origin xyz="0 0 0" rpy="0 0 0" />
      <geometry>
        <mesh filename="../meshes/dexhand021/r_f_link2_4_2.STL" />
      </geometry>
    </collision>
  </link>

  <joint name="r_f_joint2_4_2" type="fixed">
    <origin xyz="0 0 0" rpy="0 0 0" />
    <parent link="r_f_link2_4" />
    <child link="r_f_link2_4_2" />
    <axis xyz="0 0 0" />
  </joint>

  <link name="r_f_link2_3_1">
    <inertial>
      <origin xyz="0.012402519029567705 0.007714920695070759 1.755888957952506e-09" rpy="0 0 0" />
      <mass value="0.0004998303821989283" />
      <inertia ixx="1.5124255825893735e-11" ixy="-2.547965438972332e-13" ixz="1.430651712144926e-16" iyy="1.713520438388164e-11" iyz="-1.9604892907397644e-16" izz="4.9359960447248415e-12" />
    </inertial>
    <visual>
      <origin xyz="0 0 0" rpy="0 0 0" />
      <geometry>
        <mesh filename="../meshes/dexhand021/r_f_link2_3_1.STL" />
      </geometry>
      <material name="">
        <color rgba="0.3 0.3 0.3 1" />
      </material>
    </visual>
    <collision>
      <origin xyz="0 0 0" rpy="0 0 0" />
      <geometry>
        <mesh filename="../meshes/dexhand021/r_f_link2_3_1.STL" />
      </geometry>
    </collision>
  </link>

  <joint name="r_f_joint2_3_1" type="fixed">
    <origin xyz="0 0 0" rpy="0 0 0" />
    <parent link="r_f_link2_3" />
    <child link="r_f_link2_3_1" />
    <axis xyz="0 0 0" />
  </joint>

  <link name="r_f_link2_3_2">
    <inertial>
      <origin xyz="0.012938248197779298 -0.004966379635972421 -5.799490468577361e-07" rpy="0 0 0" />
      <mass value="0.0009265838824928239" />
      <inertia ixx="5.3433679145874943e-11" ixy="7.112721953915515e-13" ixz="4.7564367158810995e-15" iyy="7.063684996215453e-11" iyz="-9.60224831921344e-16" izz="4.7559278625456204e-11" />
    </inertial>
    <visual>
      <origin xyz="0 0 0" rpy="0 0 0" />
      <geometry>
        <mesh filename="../meshes/dexhand021/r_f_link2_3_2.STL" />
      </geometry>
      <material name="">
        <color rgba="0.9 0.9 0.9 1" />
      </material>
    </visual>
    <collision>
      <origin xyz="0 0 0" rpy="0 0 0" />
      <geometry>
        <mesh filename="../meshes/dexhand021/r_f_link2_3_2.STL" />
      </geometry>
    </collision>
  </link>

  <joint name="r_f_joint2_3_2" type="fixed">
    <origin xyz="0 0 0" rpy="0 0 0" />
    <parent link="r_f_link2_3" />
    <child link="r_f_link2_3_2" />
    <axis xyz="0 0 0" />
  </joint>

  <link name="r_f_link2_2_1">
    <inertial>
      <origin xyz="0.020377386408224958 0.008105578472315775 -1.8358287781288275e-09" rpy="0 0 0" />
      <mass value="0.0009340644343559288" />
      <inertia ixx="2.7202530997482942e-11" ixy="2.31883057767335e-12" ixz="1.4872477691445135e-15" iyy="6.511791793415128e-11" iyz="-3.004826771360309e-17" izz="4.1669289501571996e-11" />
    </inertial>
    <visual>
      <origin xyz="0 0 0" rpy="0 0 0" />
      <geometry>
        <mesh filename="../meshes/dexhand021/r_f_link2_2_1.STL" />
      </geometry>
      <material name="">
        <color rgba="0.3 0.3 0.3 1" />
      </material>
    </visual>
    <collision>
      <origin xyz="0 0 0" rpy="0 0 0" />
      <geometry>
        <mesh filename="../meshes/dexhand021/r_f_link2_2_1.STL" />
      </geometry>
    </collision>
  </link>

  <joint name="r_f_joint2_2_1" type="fixed">
    <origin xyz="0 0 0" rpy="0 0 0" />
    <parent link="r_f_link2_2" />
    <child link="r_f_link2_2_1" />
    <axis xyz="0 0 0" />
  </joint>

  <link name="r_f_link2_2_2">
    <inertial>
      <origin xyz="0.021873800021975243 -0.002965944865835189 3.4265420049028122e-06" rpy="0 0 0" />
      <mass value="0.00267996297249627" />
      <inertia ixx="2.461062629288351e-10" ixy="5.789691117977975e-12" ixz="1.382548467471143e-13" iyy="6.713031343525959e-10" iyz="6.22866562002737e-14" izz="5.92220288325112e-10" />
    </inertial>
    <visual>
      <origin xyz="0 0 0" rpy="0 0 0" />
      <geometry>
        <mesh filename="../meshes/dexhand021/r_f_link2_2_2.STL" />
      </geometry>
      <material name="">
        <color rgba="0.9 0.9 0.9 1" />
      </material>
    </visual>
    <collision>
      <origin xyz="0 0 0" rpy="0 0 0" />
      <geometry>
        <mesh filename="../meshes/dexhand021/r_f_link2_2_2.STL" />
      </geometry>
    </collision>
  </link>

  <joint name="r_f_joint2_2_2" type="fixed">
    <origin xyz="0 0 0" rpy="0 0 0" />
    <parent link="r_f_link2_2" />
    <child link="r_f_link2_2_2" />
    <axis xyz="0 0 0" />
  </joint>
  <link name="r_f_link3_1">
    <inertial>
      <origin xyz="0.008006862311855678 1.833886057219046e-05 -0.0015842278080930483" rpy="0 0 0" />
      <mass value="0.003518579086791124" />
      <inertia ixx="2.3066990066794662e-10" ixy="-8.218728590072904e-13" ixz="4.8904269656186795e-11" iyy="3.719848171743812e-10" iyz="-1.5962544309061537e-13" izz="2.980052968729273e-10" />
    </inertial>
    <visual>
      <origin xyz="0 0 0" rpy="0 0 0" />
      <geometry>
        <mesh filename="../meshes/dexhand021/r_f_link3_1.STL" />
      </geometry>
      <material name="">
        <color rgba="0.9 0.9 0.9 1" />
      </material>
    </visual>
    <collision>
      <origin xyz="0 0 0" rpy="0 0 0" />
      <geometry>
        <mesh filename="../meshes/dexhand021/r_f_link3_1.STL" />
      </geometry>
    </collision>
  </link>

  <joint name="r_f_joint3_1" type="revolute">
    <origin xyz="-0.010612 0.006966 0.3387" rpy="-1.5708 -1.5708 0" />
    <parent link="r_p_link0" />
    <child link="r_f_link3_1" />
    <axis xyz="0 0 1" />
    <limit lower="-0.001" upper="0.001" effort="10" velocity="1.5" />
  </joint>

  <link name="r_f_link3_2">
    <inertial>
      <origin xyz="0.0214446795509126 -0.0004628949089306857 -0.00047869270898023646" rpy="0 0 0" />
      <mass value="0.004989367448661263" />
      <inertia ixx="2.0644763911347885e-10" ixy="8.780455972493084e-12" ixz="-2.95579869573802e-13" iyy="1.0552014748311843e-09" iyz="-9.019287841379944e-13" izz="1.040162532323615e-09" />
    </inertial>
    <visual>
      <origin xyz="0 0 0" rpy="0 0 0" />
      <geometry>
        <mesh filename="../meshes/dexhand021/r_f_link3_2.STL" />
      </geometry>
      <material name="">
        <color rgba="0.3 0.3 0.3 1" />
      </material>
    </visual>
    <collision>
      <origin xyz="0 0 0" rpy="0 0 0" />
      <geometry>
        <mesh filename="../meshes/dexhand021/r_f_link3_2.STL" />
      </geometry>
    </collision>
  </link>

  <joint name="r_f_joint3_2" type="revolute">
    <origin xyz="0.017 0 0" rpy="1.5708 0 0" />
    <parent link="r_f_link3_1" />
    <child link="r_f_link3_2" />
    <axis xyz="0 0 1" />
    <limit lower="0" upper="1.3" effort="10" velocity="1.5" />
    <joint_properties damping="0.3" friction="0.5" />
  </joint>

  <link name="r_f_link3_3">
    <inertial>
      <origin xyz="0.0132803286926748 -0.0006199315921702265 -1.786332165976888e-05" rpy="0 0 0" />
      <mass value="0.0033203328984138664" />
      <inertia ixx="9.569221204957329e-11" ixy="1.0826362598445498e-11" ixz="-1.618171363264896e-12" iyy="3.0778931592210784e-10" iyz="-8.827964274285192e-14" izz="3.206404029300592e-10" />
    </inertial>
    <visual>
      <origin xyz="0 0 0" rpy="0 0 0" />
      <geometry>
        <mesh filename="../meshes/dexhand021/r_f_link3_3.STL" />
      </geometry>
      <material name="">
        <color rgba="0.3 0.3 0.3 1" />
      </material>
    </visual>
    <collision>
      <origin xyz="0 0 0" rpy="0 0 0" />
      <geometry>
        <mesh filename="../meshes/dexhand021/r_f_link3_3.STL" />
      </geometry>
    </collision>
  </link>

  <joint name="r_f_joint3_3" type="revolute">
    <origin xyz="0.043 0 0" rpy="0 0 0" />
    <parent link="r_f_link3_2" />
    <child link="r_f_link3_3" />
    <axis xyz="0 0 1" />
    <limit lower="0" upper="1.3" effort="10" velocity="1.5" />
    <joint_properties damping="0.3" friction="0.5" />
  </joint>

  <link name="r_f_link3_4">
    <inertial>
      <origin xyz="0.016835724143235947 -0.002545133894915793 -2.3757913431007993e-06" rpy="0 0 0" />
      <mass value="0.00435295281947875" />
      <inertia ixx="1.7269823391501509e-10" ixy="7.185121765445112e-11" ixz="1.0129621334840551e-13" iyy="5.470938127334459e-10" iyz="-4.5841181377205926e-14" izz="5.330028957389768e-10" />
    </inertial>
    <visual>
      <origin xyz="0 0 0" rpy="0 0 0" />
      <geometry>
        <mesh filename="../meshes/dexhand021/r_f_link3_4.STL" />
      </geometry>
      <material name="">
        <color rgba="0.3 0.3 0.3 1" />
      </material>
    </visual>
    <collision>
      <origin xyz="0 0 0" rpy="0 0 0" />
      <geometry>
        <mesh filename="../meshes/dexhand021/r_f_link3_4.STL" />
      </geometry>
    </collision>
  </link>

  <joint name="r_f_joint3_4" type="revolute">
    <origin xyz="0.025 0 0" rpy="0 0 0" />
    <parent link="r_f_link3_3" />
    <child link="r_f_link3_4" />
    <axis xyz="0 0 1" />
    <limit lower="0" upper="1.3" effort="10" velocity="1.5" />
    <joint_properties damping="0.3" friction="0.5" />
  </joint>

  <link name="r_f_link3_4_1">
    <inertial>
      <origin xyz="0.00973842245457717 0.005930029867600307 5.184462774227637e-07" rpy="0 0 0" />
      <mass value="0.00038943301930674805" />
      <inertia ixx="1.1761888707665838e-11" ixy="-1.9209378389904087e-13" ixz="1.1862850720234711e-15" iyy="1.3432121472297113e-11" iyz="1.5284550934109045e-16" izz="3.3280605712688587e-12" />
    </inertial>
    <visual>
      <origin xyz="0 0 0" rpy="0 0 0" />
      <geometry>
        <mesh filename="../meshes/dexhand021/r_f_link3_4_1.STL" />
      </geometry>
      <material name="">
        <color rgba="0.3 0.3 0.3 1" />
      </material>
    </visual>
    <collision>
      <origin xyz="0 0 0" rpy="0 0 0" />
      <geometry>
        <mesh filename="../meshes/dexhand021/r_f_link3_4_1.STL" />
      </geometry>
    </collision>
  </link>

  <joint name="r_f_joint3_4_1" type="fixed">
    <origin xyz="0 0 0" rpy="0 0 0" />
    <parent link="r_f_link3_4" />
    <child link="r_f_link3_4_1" />
    <axis xyz="0 0 0" />
  </joint>

  <link name="r_f_link3_4_2">
    <inertial>
      <origin xyz="0.01543318387448119 -0.006148726611295269 1.6634813380393825e-06" rpy="0 0 0" />
      <mass value="0.0019468121669157683" />
      <inertia ixx="1.430240549955516e-10" ixy="4.887309879653706e-11" ixz="-5.6806065428602425e-14" iyy="3.262574395389442e-10" iyz="7.694507632569444e-15" izz="2.8666011854347663e-10" />
    </inertial>
    <visual>
      <origin xyz="0 0 0" rpy="0 0 0" />
      <geometry>
        <mesh filename="../meshes/dexhand021/r_f_link3_4_2.STL" />
      </geometry>
      <material name="">
        <color rgba="0.9 0.9 0.9 1" />
      </material>
    </visual>
    <collision>
      <origin xyz="0 0 0" rpy="0 0 0" />
      <geometry>
        <mesh filename="../meshes/dexhand021/r_f_link3_4_2.STL" />
      </geometry>
    </collision>
  </link>

  <joint name="r_f_joint3_4_2" type="fixed">
    <origin xyz="0 0 0" rpy="0 0 0" />
    <parent link="r_f_link3_4" />
    <child link="r_f_link3_4_2" />
    <axis xyz="0 0 0" />
  </joint>

  <link name="r_f_link3_3_1">
    <inertial>
      <origin xyz="0.01240251902956771 0.007714920695070754 1.7558889534359512e-09" rpy="0 0 0" />
      <mass value="0.000499830382198927" />
      <inertia ixx="1.5124255825893716e-11" ixy="-2.5479654389723967e-13" ixz="1.430651712179438e-16" iyy="1.713520438388164e-11" iyz="-1.960489290658667e-16" izz="4.935996044724816e-12" />
    </inertial>
    <visual>
      <origin xyz="0 0 0" rpy="0 0 0" />
      <geometry>
        <mesh filename="../meshes/dexhand021/r_f_link3_3_1.STL" />
      </geometry>
      <material name="">
        <color rgba="0.9 0.9 0.9 1" />
      </material>
    </visual>
    <collision>
      <origin xyz="0 0 0" rpy="0 0 0" />
      <geometry>
        <mesh filename="../meshes/dexhand021/r_f_link3_3_1.STL" />
      </geometry>
    </collision>
  </link>

  <joint name="r_f_joint3_3_1" type="fixed">
    <origin xyz="0 0 0" rpy="0 0 0" />
    <parent link="r_f_link3_3" />
    <child link="r_f_link3_3_1" />
    <axis xyz="0 0 0" />
  </joint>

  <link name="r_f_link3_3_2">
    <inertial>
      <origin xyz="0.012938248197779308 -0.004966379635972423 -5.799490468601163e-07" rpy="0 0 0" />
      <mass value="0.0009265838824928244" />
      <inertia ixx="5.343367914587498e-11" ixy="7.112721953916032e-13" ixz="4.756436715900807e-15" iyy="7.063684996215463e-11" iyz="-9.602248319345149e-16" izz="4.7559278625456334e-11" />
    </inertial>
    <visual>
      <origin xyz="0 0 0" rpy="0 0 0" />
      <geometry>
        <mesh filename="../meshes/dexhand021/r_f_link3_3_2.STL" />
      </geometry>
      <material name="">
        <color rgba="0.9 0.9 0.9 1" />
      </material>
    </visual>
    <collision>
      <origin xyz="0 0 0" rpy="0 0 0" />
      <geometry>
        <mesh filename="../meshes/dexhand021/r_f_link3_3_2.STL" />
      </geometry>
    </collision>
  </link>

  <joint name="r_f_joint3_3_2" type="fixed">
    <origin xyz="0 0 0" rpy="0 0 0" />
    <parent link="r_f_link3_3" />
    <child link="r_f_link3_3_2" />
    <axis xyz="0 0 0" />
  </joint>

  <link name="r_f_link3_2_1">
    <inertial>
      <origin xyz="0.020377386408302157 0.00810557847223745 -1.8357669268881134e-09" rpy="0 0 0" />
      <mass value="0.0009340644343708481" />
      <inertia ixx="2.720253099816759e-11" ixy="2.3188305780266596e-12" ixz="1.4872474913601505e-15" iyy="6.511791793480501e-11" iyz="-3.0047943705125305e-17" izz="4.166928950230157e-11" />
    </inertial>
    <visual>
      <origin xyz="0 0 0" rpy="0 0 0" />
      <geometry>
        <mesh filename="../meshes/dexhand021/r_f_link3_2_1.STL" />
      </geometry>
      <material name="">
        <color rgba="0.3 0.3 0.3 1" />
      </material>
    </visual>
    <collision>
      <origin xyz="0 0 0" rpy="0 0 0" />
      <geometry>
        <mesh filename="../meshes/dexhand021/r_f_link3_2_1.STL" />
      </geometry>
    </collision>
  </link>

  <joint name="r_f_link3_2_1" type="fixed">
    <origin xyz="0 0 0" rpy="0 0 0" />
    <parent link="r_f_link3_2" />
    <child link="r_f_link3_2_1" />
    <axis xyz="0 0 0" />
  </joint>

  <link name="r_f_link3_2_2">
    <inertial>
      <origin xyz="0.02187380002158159 -0.0029659448659418693 3.426541867550771e-06" rpy="0 0 0" />
      <mass value="0.0026799629725441426" />
      <inertia ixx="2.46106262933417e-10" ixy="5.7896911116993384e-12" ixz="1.3825483861861467e-13" iyy="6.713031343787116e-10" iyz="6.228665402436511e-14" izz="5.922202883500953e-10" />
    </inertial>
    <visual>
      <origin xyz="0 0 0" rpy="0 0 0" />
      <geometry>
        <mesh filename="../meshes/dexhand021/r_f_link3_2_2.STL" />
      </geometry>
      <material name="">
        <color rgba="0.9 0.9 0.9 1" />
      </material>
    </visual>
    <collision>
      <origin xyz="0 0 0" rpy="0 0 0" />
      <geometry>
        <mesh filename="../meshes/dexhand021/r_f_link3_2_2.STL" />
      </geometry>
    </collision>
  </link>

  <joint name="r_f_joint3_2_2" type="fixed">
    <origin xyz="0 0 0" rpy="0 0 0" />
    <parent link="r_f_link3_2" />
    <child link="r_f_link3_2_2" />
    <axis xyz="0 0 0" />
  </joint>

  <link name="r_f_link4_1">
    <inertial>
      <origin xyz="0.008006862311855783 1.8338860572211737e-05 -0.0015842278080930808" rpy="0 0 0" />
      <mass value="0.003518579086791169" />
      <inertia ixx="2.3066990066794698e-10" ixy="-8.218728590086198e-13" ixz="4.890426965618508e-11" iyy="3.7198481717438635e-10" iyz="-1.5962544309071066e-13" izz="2.980052968729333e-10" />
    </inertial>
    <visual>
      <origin xyz="0 0 0" rpy="0 0 0" />
      <geometry>
        <mesh filename="../meshes/dexhand021/r_f_link4_1.STL" />
      </geometry>
      <material name="">
        <color rgba="0.9 0.9 0.9 1" />
      </material>
    </visual>
    <collision>
      <origin xyz="0 0 0" rpy="0 0 0" />
      <geometry>
        <mesh filename="../meshes/dexhand021/r_f_link4_1.STL" />
      </geometry>
    </collision>
  </link>

  <joint name="r_f_joint4_1" type="revolute">
    <origin xyz="0.013688 0.006966 0.3297" rpy="-1.5708 -1.5708 0" />
    <parent link="r_p_link0" />
    <child link="r_f_link4_1" />
    <axis xyz="0 0 1" />
    <limit lower="0" upper="0.6" effort="10" velocity="1.5" />
    <joint_properties damping="0.3" friction="0.5" />
  </joint>

  <link name="r_f_link4_2">
    <inertial>
      <origin xyz="0.021444679550906676 -0.00046289490893104815 -0.0004786927089766433" rpy="0 0 0" />
      <mass value="0.004989367448655343" />
      <inertia ixx="2.064476391134477e-10" ixy="8.78045597250818e-12" ixz="-2.9557986970972456e-13" iyy="1.0552014748310247e-09" iyz="-9.019287841432915e-13" izz="1.0401625323234897e-09" />
    </inertial>
    <visual>
      <origin xyz="0 0 0" rpy="0 0 0" />
      <geometry>
        <mesh filename="../meshes/dexhand021/r_f_link4_2.STL" />
      </geometry>
      <material name="">
        <color rgba="0.3 0.3 0.3 1" />
      </material>
    </visual>
    <collision>
      <origin xyz="0 0 0" rpy="0 0 0" />
      <geometry>
        <mesh filename="../meshes/dexhand021/r_f_link4_2.STL" />
      </geometry>
    </collision>
  </link>

  <joint name="r_f_joint4_2" type="revolute">
    <origin xyz="0.017 0 0" rpy="1.5708 0 0" />
    <parent link="r_f_link4_1" />
    <child link="r_f_link4_2" />
    <axis xyz="0 0 1" />
    <limit lower="0" upper="1.3" effort="10" velocity="1.5" />
    <joint_properties damping="0.3" friction="0.5" />
  </joint>

  <link name="r_f_link4_3">
    <inertial>
      <origin xyz="0.013280328692675118 -0.0006199315921702536 -1.7863321659824374e-05" rpy="0 0 0" />
      <mass value="0.0033203328984136053" />
      <inertia ixx="9.569221204956856e-11" ixy="1.0826362598447786e-11" ixz="-1.6181713632650622e-12" iyy="3.077893159220978e-10" iyz="-8.827964274264372e-14" izz="3.2064040293005174e-10" />
    </inertial>
    <visual>
      <origin xyz="0 0 0" rpy="0 0 0" />
      <geometry>
        <mesh filename="../meshes/dexhand021/r_f_link4_3.STL" />
      </geometry>
      <material name="">
        <color rgba="0.3 0.3 0.3 1" />
      </material>
    </visual>
    <collision>
      <origin xyz="0 0 0" rpy="0 0 0" />
      <geometry>
        <mesh filename="../meshes/dexhand021/r_f_link4_3.STL" />
      </geometry>
    </collision>
  </link>

  <joint name="r_f_joint4_3" type="revolute">
    <origin xyz="0.043 0 0" rpy="0 0 0" />
    <parent link="r_f_link4_2" />
    <child link="r_f_link4_3" />
    <axis xyz="0 0 1" />
    <limit lower="0" upper="1.3" effort="10" velocity="1.5" />
    <joint_properties damping="0.3" friction="0.5" />
  </joint>

  <link name="r_f_link4_4">
    <inertial>
      <origin xyz="0.016835724142979052 -0.002545133895002117 -2.3757912991866514e-06" rpy="0 0 0" />
      <mass value="0.004352952819355013" />
      <inertia ixx="1.726982339129985e-10" ixy="7.185121765660962e-11" ixz="1.0129621084417931e-13" iyy="5.470938127189919e-10" iyz="-4.5841181436560187e-14" izz="5.330028957234556e-10" />
    </inertial>
    <visual>
      <origin xyz="0 0 0" rpy="0 0 0" />
      <geometry>
        <mesh filename="../meshes/dexhand021/r_f_link4_4.STL" />
      </geometry>
      <material name="">
        <color rgba="0.3 0.3 0.3 1" />
      </material>
    </visual>
    <collision>
      <origin xyz="0 0 0" rpy="0 0 0" />
      <geometry>
        <mesh filename="../meshes/dexhand021/r_f_link4_4.STL" />
      </geometry>
    </collision>
  </link>

  <joint name="r_f_joint4_4" type="revolute">
    <origin xyz="0.025 0 0" rpy="0 0 0" />
    <parent link="r_f_link4_3" />
    <child link="r_f_link4_4" />
    <axis xyz="0 0 1" />
    <limit lower="0" upper="1.3" effort="10" velocity="1.5" />
    <joint_properties damping="0.3" friction="0.5" />
  </joint>

  <link name="r_f_link4_4_1">
    <inertial>
      <origin xyz="0.00973842245459893 0.005930029867598804 5.184462258307792e-07" rpy="0 0 0" />
      <mass value="0.00038943301930773646" />
      <inertia ixx="1.1761888707777006e-11" ixy="-1.920937838807718e-13" ixz="1.1862851425339631e-15" iyy="1.3432121472446846e-11" iyz="1.5284543351363473e-16" izz="3.328060571257918e-12" />
    </inertial>
    <visual>
      <origin xyz="0 0 0" rpy="0 0 0" />
      <geometry>
        <mesh filename="../meshes/dexhand021/r_f_link4_4_1.STL" />
      </geometry>
      <material name="">
        <color rgba="0.3 0.3 0.3 1" />
      </material>
    </visual>
    <collision>
      <origin xyz="0 0 0" rpy="0 0 0" />
      <geometry>
        <mesh filename="../meshes/dexhand021/r_f_link4_4_1.STL" />
      </geometry>
    </collision>
  </link>

  <joint name="r_f_joint4_4_1" type="fixed">
    <origin xyz="0 0 0" rpy="0 0 0" />
    <parent link="r_f_link4_4" />
    <child link="r_f_link4_4_1" />
    <axis xyz="0 0 0" />
  </joint>

  <link name="r_f_link4_4_2">
    <inertial>
      <origin xyz="0.015433183877996647 -0.006148726613474619 1.663483296615289e-06" rpy="0 0 0" />
      <mass value="0.0019468121676849014" />
      <inertia ixx="1.4302405503805388e-10" ixy="4.8873098834891383e-11" ixz="-5.680609950280635e-14" iyy="3.2625743962275807e-10" iyz="7.694528690012234e-15" izz="2.866601186317795e-10" />
    </inertial>
    <visual>
      <origin xyz="0 0 0" rpy="0 0 0" />
      <geometry>
        <mesh filename="../meshes/dexhand021/r_f_link4_4_2.STL" />
      </geometry>
      <material name="">
        <color rgba="0.9 0.9 0.9 1" />
      </material>
    </visual>
    <collision>
      <origin xyz="0 0 0" rpy="0 0 0" />
      <geometry>
        <mesh filename="../meshes/dexhand021/r_f_link4_4_2.STL" />
      </geometry>
    </collision>
  </link>

  <joint name="r_f_joint4_4_2" type="fixed">
    <origin xyz="0 0 0" rpy="0 0 0" />
    <parent link="r_f_link4_4" />
    <child link="r_f_link4_4_2" />
    <axis xyz="0 0 0" />
  </joint>

  <link name="r_f_link4_3_2">
    <inertial>
      <origin xyz="0.01293824819777932 -0.004966379635972429 -5.799490468630916e-07" rpy="0 0 0" />
      <mass value="0.0009265838824928253" />
      <inertia ixx="5.343367914587497e-11" ixy="7.112721953916162e-13" ixz="4.75643671594095e-15" iyy="7.063684996215479e-11" iyz="-9.602248319449432e-16" izz="4.755927862545644e-11" />
    </inertial>
    <visual>
      <origin xyz="0 0 0" rpy="0 0 0" />
      <geometry>
        <mesh filename="../meshes/dexhand021/r_f_link4_3_2.STL" />
      </geometry>
      <material name="">
        <color rgba="0.9 0.9 0.9 1" />
      </material>
    </visual>
    <collision>
      <origin xyz="0 0 0" rpy="0 0 0" />
      <geometry>
        <mesh filename="../meshes/dexhand021/r_f_link4_3_2.STL" />
      </geometry>
    </collision>
  </link>

  <joint name="r_f_joint4_3_2" type="fixed">
    <origin xyz="0 0 0" rpy="0 0 0" />
    <parent link="r_f_link4_3" />
    <child link="r_f_link4_3_2" />
    <axis xyz="0 0 0" />
  </joint>

  <link name="r_f_link4_3_1">
    <inertial>
      <origin xyz="0.012402519029617028 0.007714920695189423 1.7562179048963857e-09" rpy="0 0 0" />
      <mass value="0.000499830382166977" />
      <inertia ixx="1.5124255824896737e-11" ixy="-2.547965438512665e-13" ixz="1.4306529804306635e-16" iyy="1.713520438301633e-11" iyz="-1.9604862408080833e-16" izz="4.935996044555076e-12" />
    </inertial>
    <visual>
      <origin xyz="0 0 0" rpy="0 0 0" />
      <geometry>
        <mesh filename="../meshes/dexhand021/r_f_link4_3_1.STL" />
      </geometry>
      <material name="">
        <color rgba="0.3 0.3 0.3 1" />
      </material>
    </visual>
    <collision>
      <origin xyz="0 0 0" rpy="0 0 0" />
      <geometry>
        <mesh filename="../meshes/dexhand021/r_f_link4_3_1.STL" />
      </geometry>
    </collision>
  </link>

  <joint name="r_f_joint4_3_1" type="fixed">
    <origin xyz="0 0 0" rpy="0 0 0" />
    <parent link="r_f_link4_3" />
    <child link="r_f_link4_3_1" />
    <axis xyz="0 0 0" />
  </joint>

  <link name="r_f_link4_2_1">
    <inertial>
      <origin xyz="0.020377386408241372 0.00810557847230356 -1.8358250730400228e-09" rpy="0 0 0" />
      <mass value="0.0009340644343591204" />
      <inertia ixx="2.720253099758899e-11" ixy="2.31883057772797e-12" ixz="1.4872477534318148e-15" iyy="6.511791793427608e-11" iyz="-3.0048229349295313e-17" izz="4.166928950170176e-11" />
    </inertial>
    <visual>
      <origin xyz="0 0 0" rpy="0 0 0" />
      <geometry>
        <mesh filename="../meshes/dexhand021/r_f_link4_2_1.STL" />
      </geometry>
      <material name="">
        <color rgba="0.3 0.3 0.3 1" />
      </material>
    </visual>
    <collision>
      <origin xyz="0 0 0" rpy="0 0 0" />
      <geometry>
        <mesh filename="../meshes/dexhand021/r_f_link4_2_1.STL" />
      </geometry>
    </collision>
  </link>

  <joint name="r_f_joint4_2_1" type="fixed">
    <origin xyz="0 0 0" rpy="0 0 0" />
    <parent link="r_f_link4_2" />
    <child link="r_f_link4_2_1" />
    <axis xyz="0 0 0" />
  </joint>

  <link name="r_f_link4_2_2">
    <inertial>
      <origin xyz="0.021873800021581503 -0.0029659448659418606 3.4265418675301423e-06" rpy="0 0 0" />
      <mass value="0.002679962972544183" />
      <inertia ixx="2.4610626293342107e-10" ixy="5.789691111700734e-12" ixz="1.3825483861862083e-13" iyy="6.713031343787191e-10" iyz="6.228665402431011e-14" izz="5.922202883501009e-10" />
    </inertial>
    <visual>
      <origin xyz="0 0 0" rpy="0 0 0" />
      <geometry>
        <mesh filename="../meshes/dexhand021/r_f_link4_2_2.STL" />
      </geometry>
      <material name="">
        <color rgba="0.9 0.9 0.9 1" />
      </material>
    </visual>
    <collision>
      <origin xyz="0 0 0" rpy="0 0 0" />
      <geometry>
        <mesh filename="../meshes/dexhand021/r_f_link4_2_2.STL" />
      </geometry>
    </collision>
  </link>

  <joint name="r_f_joint4_2_2" type="fixed">
    <origin xyz="0 0 0" rpy="0 0 0" />
    <parent link="r_f_link4_2" />
    <child link="r_f_link4_2_2" />
    <axis xyz="0 0 0" />
  </joint>

  <link name="r_f_link5_1">
    <inertial>
      <origin xyz="0.008006862311856088 1.833886057228032e-05 -0.0015842278080930164" rpy="0 0 0" />
      <mass value="0.003518579086791241" />
      <inertia ixx="2.3066990066794766e-10" ixy="-8.218728590113507e-13" ixz="4.890426965618449e-11" iyy="3.719848171743997e-10" iyz="-1.5962544309106418e-13" izz="2.9800529687294687e-10" />
    </inertial>
    <visual>
      <origin xyz="0 0 0" rpy="0 0 0" />
      <geometry>
        <mesh filename="../meshes/dexhand021/r_f_link5_1.STL" />
      </geometry>
      <material name="">
        <color rgba="0.9 0.9 0.9 1" />
      </material>
    </visual>
    <collision>
      <origin xyz="0 0 0" rpy="0 0 0" />
      <geometry>
        <mesh filename="../meshes/dexhand021/r_f_link5_1.STL" />
      </geometry>
    </collision>
  </link>

  <joint name="r_f_joint5_1" type="revolute">
    <origin xyz="0.037988 0.006966 0.3157" rpy="-1.5708 -1.5708 0" />
    <parent link="r_p_link0" />
    <child link="r_f_link5_1" />
    <axis xyz="0 0 1" />
    <limit lower="0" upper="0.6" effort="10" velocity="1.5" />
    <joint_properties damping="0.3" friction="0.5" />
  </joint>

  <link name="r_f_link5_2">
    <inertial>
      <origin xyz="0.021444679550906603 -0.0004628949089313295 -0.0004786927089768149" rpy="0 0 0" />
      <mass value="0.004989367448655121" />
      <inertia ixx="2.0644763911342806e-10" ixy="8.78045597248202e-12" ixz="-2.955798697224554e-13" iyy="1.0552014748309056e-09" iyz="-9.019287841410571e-13" izz="1.0401625323233743e-09" />
    </inertial>
    <visual>
      <origin xyz="0 0 0" rpy="0 0 0" />
      <geometry>
        <mesh filename="../meshes/dexhand021/r_f_link5_2.STL" />
      </geometry>
      <material name="">
        <color rgba="0.3 0.3 0.3 1" />
      </material>
    </visual>
    <collision>
      <origin xyz="0 0 0" rpy="0 0 0" />
      <geometry>
        <mesh filename="../meshes/dexhand021/r_f_link5_2.STL" />
      </geometry>
    </collision>
  </link>

  <joint name="r_f_joint5_2" type="revolute">
    <origin xyz="0.017 0 0" rpy="1.5708 0 0" />
    <parent link="r_f_link5_1" />
    <child link="r_f_link5_2" />
    <axis xyz="0 0 1" />
    <limit lower="0" upper="1.3" effort="10" velocity="1.5" />
    <joint_properties damping="0.3" friction="0.5" />
  </joint>

  <link name="r_f_link5_3">
    <inertial>
      <origin xyz="0.013280328692676044 -0.0006199315921701265 -1.7863321659867563e-05" rpy="0 0 0" />
      <mass value="0.003320332898413456" />
      <inertia ixx="9.569221204956008e-11" ixy="1.0826362598447573e-11" ixz="-1.618171363270022e-12" iyy="3.07789315922064e-10" iyz="-8.8279642739463e-14" izz="3.2064040293000584e-10" />
    </inertial>
    <visual>
      <origin xyz="0 0 0" rpy="0 0 0" />
      <geometry>
        <mesh filename="../meshes/dexhand021/r_f_link5_3.STL" />
      </geometry>
      <material name="">
        <color rgba="0.3 0.3 0.3 1" />
      </material>
    </visual>
    <collision>
      <origin xyz="0 0 0" rpy="0 0 0" />
      <geometry>
        <mesh filename="../meshes/dexhand021/r_f_link5_3.STL" />
      </geometry>
    </collision>
  </link>

  <joint name="r_f_joint5_3" type="revolute">
    <origin xyz="0.043 0 0" rpy="0 0 0" />
    <parent link="r_f_link5_2" />
    <child link="r_f_link5_3" />
    <axis xyz="0 0 1" />
    <limit lower="0" upper="1.3" effort="10" velocity="1.5" />
    <joint_properties damping="0.3" friction="0.5" />
  </joint>

  <link name="r_f_link5_4">
    <inertial>
      <origin xyz="0.016835724193078983 -0.0025451339066119762 -2.375807710636194e-06" rpy="0 0 0" />
      <mass value="0.004352952855182437" />
      <inertia ixx="1.7269823605837295e-10" ixy="7.185121819458006e-11" ixz="1.0129642288770988e-13" iyy="5.47093816724279e-10" iyz="-4.58411448890324e-14" izz="5.330028980487819e-10" />
    </inertial>
    <visual>
      <origin xyz="0 0 0" rpy="0 0 0" />
      <geometry>
        <mesh filename="../meshes/dexhand021/r_f_link5_4.STL" />
      </geometry>
      <material name="">
        <color rgba="0.3 0.3 0.3 1" />
      </material>
    </visual>
    <collision>
      <origin xyz="0 0 0" rpy="0 0 0" />
      <geometry>
        <mesh filename="../meshes/dexhand021/r_f_link5_4.STL" />
      </geometry>
    </collision>
  </link>

  <joint name="r_f_joint5_4" type="revolute">
    <origin xyz="0.025 0 0" rpy="0 0 0" />
    <parent link="r_f_link5_3" />
    <child link="r_f_link5_4" />
    <axis xyz="0 0 1" />
    <limit lower="0" upper="1.3" effort="10" velocity="1.5" />
    <joint_properties damping="0.3" friction="0.5" />
  </joint>

  <link name="r_f_link5_4_1">
    <inertial>
      <origin xyz="0.009738422454345726 0.005930029867607992 5.184464520480232e-07" rpy="0 0 0" />
      <mass value="0.0003894330192680039" />
      <inertia ixx="1.1761888706684739e-11" ixy="-1.9209378388774791e-13" ixz="1.186284566954947e-15" iyy="1.343212147099201e-11" iyz="1.5284533404108687e-16" izz="3.3280605709656388e-12" />
    </inertial>
    <visual>
      <origin xyz="0 0 0" rpy="0 0 0" />
      <geometry>
        <mesh filename="../meshes/dexhand021/r_f_link5_4_1.STL" />
      </geometry>
      <material name="">
        <color rgba="0.3 0.3 0.3 1" />
      </material>
    </visual>
    <collision>
      <origin xyz="0 0 0" rpy="0 0 0" />
      <geometry>
        <mesh filename="../meshes/dexhand021/r_f_link5_4_1.STL" />
      </geometry>
    </collision>
  </link>

  <joint name="r_f_joint5_4_1" type="fixed">
    <origin xyz="0 0 0" rpy="0 0 0" />
    <parent link="r_f_link5_4" />
    <child link="r_f_link5_4_1" />
    <axis xyz="0 0 0" />
  </joint>

  <link name="r_f_link5_4_2">
    <inertial>
      <origin xyz="0.0154331838795733 -0.006148726613435892 1.6634833667932593e-06" rpy="0 0 0" />
      <mass value="0.0019468121678303657" />
      <inertia ixx="1.4302405503834417e-10" ixy="4.887309883330095e-11" ixz="-5.680610238540891e-14" iyy="3.2625743968777927e-10" iyz="7.69452862032312e-15" izz="2.866601186965895e-10" />
    </inertial>
    <visual>
      <origin xyz="0 0 0" rpy="0 0 0" />
      <geometry>
        <mesh filename="../meshes/dexhand021/r_f_link5_4_2.STL" />
      </geometry>
      <material name="">
        <color rgba="0.9 0.9 0.9 1" />
      </material>
    </visual>
    <collision>
      <origin xyz="0 0 0" rpy="0 0 0" />
      <geometry>
        <mesh filename="../meshes/dexhand021/r_f_link5_4_2.STL" />
      </geometry>
    </collision>
  </link>

  <joint name="r_f_joint5_4_2" type="fixed">
    <origin xyz="0 0 0" rpy="0 0 0" />
    <parent link="r_f_link5_4" />
    <child link="r_f_link5_4_2" />
    <axis xyz="0 0 0" />
  </joint>

  <link name="r_f_link5_3_1">
    <inertial>
      <origin xyz="0.012402519029617032 0.007714920695189426 1.7562179048963862e-09" rpy="0 0 0" />
      <mass value="0.0004998303821669769" />
      <inertia ixx="1.5124255824896718e-11" ixy="-2.547965438512407e-13" ixz="1.4306529804306638e-16" iyy="1.713520438301628e-11" iyz="-1.9604862408123242e-16" izz="4.935996044554998e-12" />
    </inertial>
    <visual>
      <origin xyz="0 0 0" rpy="0 0 0" />
      <geometry>
        <mesh filename="../meshes/dexhand021/r_f_link5_3_1.STL" />
      </geometry>
      <material name="">
        <color rgba="0.3 0.3 0.3 1" />
      </material>
    </visual>
    <collision>
      <origin xyz="0 0 0" rpy="0 0 0" />
      <geometry>
        <mesh filename="../meshes/dexhand021/r_f_link5_3_1.STL" />
      </geometry>
    </collision>
  </link>

  <joint name="r_f_joint5_3_1" type="fixed">
    <origin xyz="0 0 0" rpy="0 0 0" />
    <parent link="r_f_link5_3" />
    <child link="r_f_link5_3_1" />
    <axis xyz="0 0 0" />
  </joint>

  <link name="r_f_link5_3_2">
    <inertial>
      <origin xyz="0.01293824819777932 -0.0049663796359724266 -5.799490468630916e-07" rpy="0 0 0" />
      <mass value="0.0009265838824928253" />
      <inertia ixx="5.343367914587496e-11" ixy="7.11272195391642e-13" ixz="4.75643671594095e-15" iyy="7.063684996215479e-11" iyz="-9.602248319449448e-16" izz="4.755927862545644e-11" />
    </inertial>
    <visual>
      <origin xyz="0 0 0" rpy="0 0 0" />
      <geometry>
        <mesh filename="../meshes/dexhand021/r_f_link5_3_2.STL" />
      </geometry>
      <material name="">
        <color rgba="0.9 0.9 0.9 1" />
      </material>
    </visual>
    <collision>
      <origin xyz="0 0 0" rpy="0 0 0" />
      <geometry>
        <mesh filename="../meshes/dexhand021/r_f_link5_3_2.STL" />
      </geometry>
    </collision>
  </link>

  <joint name="r_f_joint5_3_2" type="fixed">
    <origin xyz="0 0 0" rpy="0 0 0" />
    <parent link="r_f_link5_3" />
    <child link="r_f_link5_3_2" />
    <axis xyz="0 0 0" />
  </joint>

  <link name="r_f_link5_2_1">
    <inertial>
      <origin xyz="0.020377386408241372 0.008105578472303553 -1.8358250729477754e-09" rpy="0 0 0" />
      <mass value="0.0009340644343591205" />
      <inertia ixx="2.720253099758908e-11" ixy="2.3188305777278406e-12" ixz="1.487247753426462e-15" iyy="6.511791793427603e-11" iyz="-3.004822934795065e-17" izz="4.166928950170181e-11" />
    </inertial>
    <visual>
      <origin xyz="0 0 0" rpy="0 0 0" />
      <geometry>
        <mesh filename="../meshes/dexhand021/r_f_link5_2_1.STL" />
      </geometry>
      <material name="">
        <color rgba="0.3 0.3 0.3 1" />
      </material>
    </visual>
    <collision>
      <origin xyz="0 0 0" rpy="0 0 0" />
      <geometry>
        <mesh filename="../meshes/dexhand021/r_f_link5_2_1.STL" />
      </geometry>
    </collision>
  </link>

  <joint name="r_f_joint5_2_1" type="fixed">
    <origin xyz="0 0 0" rpy="0 0 0" />
    <parent link="r_f_link5_2" />
    <child link="r_f_link5_2_1" />
    <axis xyz="0 0 0" />
  </joint>

  <link name="r_f_link5_2_2">
    <inertial>
      <origin xyz="0.021873800021581506 -0.0029659448659418476 3.426541867502145e-06" rpy="0 0 0" />
      <mass value="0.002679962972544193" />
      <inertia ixx="2.46106262933422e-10" ixy="5.789691111700786e-12" ixz="1.3825483861714585e-13" iyy="6.71303134378717e-10" iyz="6.228665402449863e-14" izz="5.922202883500982e-10" />
    </inertial>
    <visual>
      <origin xyz="0 0 0" rpy="0 0 0" />
      <geometry>
        <mesh filename="../meshes/dexhand021/r_f_link5_2_2.STL" />
      </geometry>
      <material name="">
        <color rgba="0.9 0.9 0.9 1" />
      </material>
    </visual>
    <collision>
      <origin xyz="0 0 0" rpy="0 0 0" />
      <geometry>
        <mesh filename="../meshes/dexhand021/r_f_link5_2_2.STL" />
      </geometry>
    </collision>
  </link>

  <joint name="r_f_joint5_2_2" type="fixed">
    <origin xyz="0 0 0" rpy="0 0 0" />
    <parent link="r_f_link5_2" />
    <child link="r_f_link5_2_2" />
    <axis xyz="0 0 0" />
  </joint>
  <link name="r_p_link1">
    <inertial>
      <origin xyz="-0.03983372937532701 0.048318738836771104 -0.023220400917865352" rpy="0 0 0" />
      <mass value="0.08395173603509726" />
      <inertia ixx="3.648736072616701e-08" ixy="-3.5309381015073303e-09" ixz="-2.3605783102161306e-09" iyy="4.4254975033711677e-08" iyz="-9.066425502757339e-09" izz="1.4337820996587614e-08" />
    </inertial>
    <visual>
      <origin xyz="0 0 0" rpy="0 0 0" />
      <geometry>
        <mesh filename="../meshes/dexhand021/r_p_link1.STL" />
      </geometry>
      <material name="">
        <color rgba="0.3 0.3 0.3 1" />
      </material>
    </visual>
    <collision>
      <origin xyz="0 0 0" rpy="0 0 0" />
      <geometry>
        <mesh filename="../meshes/dexhand021/r_p_link1.STL" />
      </geometry>
    </collision>
  </link>

  <joint name="r_f_joint1" type="fixed">
    <origin xyz="-0.023855 0.032704 0.27707" rpy="0.26842 -0.15197 2.8876" />
    <parent link="r_p_link0" />
    <child link="r_p_link1" />
    <axis xyz="0 0 0" />
  </joint>

  <link name="r_p_link3">
    <inertial>
      <origin xyz="-0.023161994358886367 0.008827545164030117 0.028148918014715408" rpy="0 0 0" />
      <mass value="0.044023395748120794" />
      <inertia ixx="5.023584950777533e-09" ixy="-3.05300024440455e-09" ixz="-8.470489953474035e-10" iyy="1.471870436515504e-08" iyz="-1.1291068838601622e-09" izz="1.1859554978542593e-08" />
    </inertial>
    <visual>
      <origin xyz="0 0 0" rpy="0 0 0" />
      <geometry>
        <mesh filename="../meshes/dexhand021/r_p_link3.STL" />
      </geometry>
      <material name="">
        <color rgba="0.3 0.3 0.3 1" />
      </material>
    </visual>
    <collision>
      <origin xyz="0 0 0" rpy="0 0 0" />
      <geometry>
        <mesh filename="../meshes/dexhand021/r_p_link3.STL" />
      </geometry>
    </collision>
  </link>

  <joint name="r_f_joint3" type="fixed">
    <origin xyz="-0.023855 0.032704 0.27707" rpy="0.26842 -0.15197 2.8876" />
    <parent link="r_p_link0" />
    <child link="r_p_link3" />
    <axis xyz="0 0 0" />
  </joint>

  <link name="r_p_link4">
    <inertial>
      <origin xyz="-0.029728719311365205 -0.005167865235956345 -0.049836801625217676" rpy="0 0 0" />
      <mass value="0.08245656201270479" />
      <inertia ixx="1.54444087395338e-08" ixy="-5.4787402337217735e-09" ixz="2.1986089072122355e-09" iyy="4.24324555419933e-08" iyz="-5.694817674229571e-10" izz="3.360344779864822e-08" />
    </inertial>
    <visual>
      <origin xyz="0 0 0" rpy="0 0 0" />
      <geometry>
        <mesh filename="../meshes/dexhand021/r_p_link4.STL" />
      </geometry>
      <material name="">
        <color rgba="0.9 0.9 0.9 1" />
      </material>
    </visual>
    <collision>
      <origin xyz="0 0 0" rpy="0 0 0" />
      <geometry>
        <mesh filename="../meshes/dexhand021/r_p_link4.STL" />
      </geometry>
    </collision>
  </link>

  <joint name="r_f_joint4" type="fixed">
    <origin xyz="-0.023855 0.032704 0.27707" rpy="0.26842 -0.15197 2.8876" />
    <parent link="r_p_link0" />
    <child link="r_p_link4" />
    <axis xyz="0 0 0" />
  </joint>

  <link name="r_p_link5">
    <inertial>
      <origin xyz="-0.02256730562958097 -0.008908175434005319 -0.04271790120102455" rpy="0 0 0" />
      <mass value="0.022516997147359073" />
      <inertia ixx="2.092547751524618e-09" ixy="-1.4390176502664466e-09" ixz="7.516082402310597e-10" iyy="8.133599836241913e-09" iyz="-9.022953556464517e-11" izz="7.214731328161442e-09" />
    </inertial>
    <visual>
      <origin xyz="0 0 0" rpy="0 0 0" />
      <geometry>
        <mesh filename="../meshes/dexhand021/r_p_link5.STL" />
      </geometry>
      <material name="">
        <color rgba="0.3 0.3 0.3 1" />
      </material>
    </visual>
    <collision>
      <origin xyz="0 0 0" rpy="0 0 0" />
      <geometry>
        <mesh filename="../meshes/dexhand021/r_p_link5.STL" />
      </geometry>
    </collision>
  </link>

  <joint name="r_f_joint5" type="fixed">
    <origin xyz="-0.023855 0.032704 0.27707" rpy="0.26842 -0.15197 2.8876" />
    <parent link="r_p_link0" />
    <child link="r_p_link5" />
    <axis xyz="0 0 0" />
  </joint>

  <link name="r_p_link6">
    <inertial>
      <origin xyz="-0.03535057740967973 0.043677222866326595 -0.0050236994810133224" rpy="0 0 0" />
      <mass value="0.11253371281264385" />
      <inertia ixx="9.44598626373826e-08" ixy="-1.6398925824622036e-08" ixz="-2.0464759323204166e-09" iyy="1.4547379132523024e-07" iyz="-2.141775870879064e-08" izz="7.402784956784709e-08" />
    </inertial>
    <visual>
      <origin xyz="0 0 0" rpy="0 0 0" />
      <geometry>
        <mesh filename="../meshes/dexhand021/r_p_link6.STL" />
      </geometry>
      <material name="">
        <color rgba="0.9 0.9 0.9 1" />
      </material>
    </visual>
    <collision>
      <origin xyz="0 0 0" rpy="0 0 0" />
      <geometry>
        <mesh filename="../meshes/dexhand021/r_p_link6.STL" />
      </geometry>
    </collision>
  </link>

  <joint name="r_f_joint6" type="fixed">
    <origin xyz="-0.023855 0.032704 0.27707" rpy="0.26842 -0.15197 2.8876" />
    <parent link="r_p_link0" />
    <child link="r_p_link6" />
    <axis xyz="0 0 0" />
  </joint>

  <link name="r_p_link2">
    <inertial>
      <origin xyz="-0.02488575295174602 0.013706703059175068 0.02016484295334375" rpy="0 0 0" />
      <mass value="0.07899657199227124" />
      <inertia ixx="1.507652832707221e-08" ixy="-9.094527046683921e-09" ixz="1.0836822261290767e-10" iyy="4.701759476226564e-08" iyz="-1.5944191236254352e-09" izz="3.98800067297972e-08" />
    </inertial>
    <visual>
      <origin xyz="0 0 0" rpy="0 0 0" />
      <geometry>
        <mesh filename="../meshes/dexhand021/r_p_link2.STL" />
      </geometry>
      <material name="">
        <color rgba="0.9 0.9 0.9 1" />
      </material>
    </visual>
    <collision>
      <origin xyz="0 0 0" rpy="0 0 0" />
      <geometry>
        <mesh filename="../meshes/dexhand021/r_p_link2.STL" />
      </geometry>
    </collision>
  </link>

  <joint name="r_f_joint2" type="fixed">
    <origin xyz="-0.023855 0.032704 0.27707" rpy="0.26842 -0.15197 2.8876" />
    <parent link="r_p_link0" />
    <child link="r_p_link2" />
    <axis xyz="0 0 0" />
  </joint>


  <link name="r_f_link1_tip">
    <inertial>
      <origin xyz="0 0 0.005" rpy="0 0 0" />
      <mass value="0.001" />
      <inertia ixx="1.0E-09" ixy="0.0" ixz="0.0" iyy="1.0E-09" iyz="0.0" izz="1.0E-09" />
    </inertial>
    <visual>
      <origin xyz="0.015 -0.004 0" rpy="0 0 0" />
      <geometry>
        <sphere radius="0.002" />
      </geometry>
      <material name="">
        <color rgba="1 0 0 1" />
      </material>
    </visual>
    <collision>
      <origin xyz="0 0 0" rpy="0 0 0" />
      <geometry>
        <sphere radius="0.002" />
      </geometry>
    </collision>
  </link>

  <joint name="r_f_joint1_tip" type="fixed">
    <origin xyz="0.02 0 0" rpy="0 0 0" />
    <parent link="r_f_link1_4" />
    <child link="r_f_link1_tip" />
  </joint>

  <link name="r_f_link2_tip">
    <inertial>
      <origin xyz="0 0 0.005" rpy="0 0 0" />
      <mass value="0.001" />
      <inertia ixx="1.0E-09" ixy="0.0" ixz="0.0" iyy="1.0E-09" iyz="0.0" izz="1.0E-09" />
    </inertial>
    <visual>
      <origin xyz="0.015 -0.004 0" rpy="0 0 0" />
      <geometry>
        <sphere radius="0.002" />
      </geometry>
      <material name="">
        <color rgba="1 0 0 1" />
      </material>
    </visual>
    <collision>
      <origin xyz="0 0 0" rpy="0 0 0" />
      <geometry>
        <sphere radius="0.002" />
      </geometry>
    </collision>
  </link>

  <joint name="r_f_joint2_tip" type="fixed">
    <origin xyz="0.02 0 0" rpy="0 0 0" />
    <parent link="r_f_link2_4" />
    <child link="r_f_link2_tip" />
  </joint>

  <link name="r_f_link3_tip">
    <inertial>
      <origin xyz="0 0 0.005" rpy="0 0 0" />
      <mass value="0.001" />
      <inertia ixx="1.0E-09" ixy="0.0" ixz="0.0" iyy="1.0E-09" iyz="0.0" izz="1.0E-09" />
    </inertial>
    <visual>
      <origin xyz="0.015 -0.004 0" rpy="0 0 0" />
      <geometry>
        <sphere radius="0.002" />
      </geometry>
      <material name="">
        <color rgba="1 0 0 1" />
      </material>
    </visual>
    <collision>
      <origin xyz="0 0 0" rpy="0 0 0" />
      <geometry>
        <sphere radius="0.002" />
      </geometry>
    </collision>
  </link>

  <joint name="r_f_joint3_tip" type="fixed">
    <origin xyz="0.02 0 0" rpy="0 0 0" />
    <parent link="r_f_link3_4" />
    <child link="r_f_link3_tip" />
  </joint>

  <link name="r_f_link4_tip">
    <inertial>
      <origin xyz="0 0 0.005" rpy="0 0 0" />
      <mass value="0.001" />
      <inertia ixx="1.0E-09" ixy="0.0" ixz="0.0" iyy="1.0E-09" iyz="0.0" izz="1.0E-09" />
    </inertial>
    <visual>
      <origin xyz="0.015 -0.004 0" rpy="0 0 0" />
      <geometry>
        <sphere radius="0.002" />
      </geometry>
      <material name="">
        <color rgba="1 0 0 1" />
      </material>
    </visual>
    <collision>
      <origin xyz="0 0 0" rpy="0 0 0" />
      <geometry>
        <sphere radius="0.002" />
      </geometry>
    </collision>
  </link>

  <joint name="r_f_joint4_tip" type="fixed">
    <origin xyz="0.02 0 0" rpy="0 0 0" />
    <parent link="r_f_link4_4" />
    <child link="r_f_link4_tip" />
  </joint>

  <link name="r_f_link5_tip">
    <inertial>
      <origin xyz="0 0 0.005" rpy="0 0 0" />
      <mass value="0.001" />
      <inertia ixx="1.0E-09" ixy="0.0" ixz="0.0" iyy="1.0E-09" iyz="0.0" izz="1.0E-09" />
    </inertial>
    <visual>
      <origin xyz="0.015 -0.004 0" rpy="0 0 0" />
      <geometry>
        <sphere radius="0.002" />
      </geometry>
      <material name="">
        <color rgba="1 0 0 1" />
      </material>
    </visual>
    <collision>
      <origin xyz="0 0 0" rpy="0 0 0" />
      <geometry>
        <sphere radius="0.002" />
      </geometry>
    </collision>
  </link>

  <joint name="r_f_joint5_tip" type="fixed">
    <origin xyz="0.02 0 0" rpy="0 0 0" />
    <parent link="r_f_link5_4" />
    <child link="r_f_link5_tip" />
  </joint>
</robot>
