<robot name="dexhand021_left_simplified">

  <mujoco>
    <compiler meshdir="../meshes/dexhand021_simplified" balanceinertia="true" discardvisual="false" />
  </mujoco>

  <link name="left_hand_base">
    <inertial>
      <origin xyz="-0.001433944695677107 -0.0010853364114898271 0.0932527558249519" rpy="0 0 0" />
      <mass value="0.8839820474170381" />
      <inertia ixx="2.09795443422357e-06" ixy="2.6881563703530053e-08" ixz="6.413855181461991e-08" iyy="1.6119578275944253e-06" iyz="9.370189502077133e-09" izz="8.995988700283038e-07" />
    </inertial>
    <visual>
      <origin xyz="0 0 0" rpy="0 0 0" />
      <geometry>
        <mesh filename="../meshes/dexhand021_simplified/left_hand_base.STL" />
      </geometry>
      <material name="">
        <color rgba="0.75294 0.75294 0.75294 1" />
      </material>
    </visual>
    <collision>
      <origin xyz="0 0 0" rpy="0 0 0" />
      <geometry>
        <mesh filename="../meshes/dexhand021_simplified/left_hand_base.STL" />
      </geometry>
    </collision>
  </link>
  <link name="l_f_link1_1">
    <inertial>
      <origin xyz="0.001980573911977284 -0.0003519916046890215 -0.013451253689896279" rpy="0 0 0" />
      <mass value="0.004409652627263485" />
      <inertia ixx="4.673103357121796e-10" ixy="4.470691365043646e-12" ixz="-4.078165731716411e-11" iyy="5.488960382446679e-10" iyz="1.074673808148834e-11" izz="2.5584978307135863e-10" />
    </inertial>
    <visual>
      <origin xyz="0 0 0" rpy="0 0 0" />
      <geometry>
        <mesh filename="../meshes/dexhand021_simplified/l_f_link1_1.STL" />
      </geometry>
      <material name="">
        <color rgba="0.6 0.6 0.6 1" />
      </material>
    </visual>
    <collision>
      <origin xyz="0 0 0" rpy="0 0 0" />
      <geometry>
        <mesh filename="../meshes/dexhand021_simplified/l_f_link1_1.STL" />
      </geometry>
    </collision>
  </link>
  <joint name="l_f_joint1_1" type="revolute">
    <origin xyz="0.032783 -0.023781 0.11211" rpy="-0.26842 -0.15197 -1.3168" />
    <parent link="left_hand_base" />
    <child link="l_f_link1_1" />
    <axis xyz="0 0 1" />
    <limit lower="0" upper="2.2" effort="10" velocity="1.5" />
    <joint_properties damping="0.3" friction="0.5" />
  </joint>
  <link name="l_f_link1_2">
    <inertial>
      <origin xyz="0.02143503770038841 0.00017993837719091317 0.0012981954412922612" rpy="0 0 0" />
      <mass value="0.009951630175659748" />
      <inertia ixx="7.760650379083414e-10" ixy="5.427072133311471e-11" ixz="1.5290052103370445e-12" iyy="2.067086168946858e-09" iyz="3.482551640695207e-13" izz="2.1373850788580625e-09" />
    </inertial>
    <visual>
      <origin xyz="0 0 0" rpy="0 0 0" />
      <geometry>
        <mesh filename="../meshes/dexhand021_simplified/l_f_link1_2.STL" />
      </geometry>
      <material name="">
        <color rgba="0.6 0.6 0.6 1" />
      </material>
    </visual>
    <collision>
      <origin xyz="0 0 0" rpy="0 0 0" />
      <geometry>
        <mesh filename="../meshes/dexhand021_simplified/l_f_link1_2.STL" />
      </geometry>
    </collision>
  </link>
  <joint name="l_f_joint1_2" type="revolute">
    <origin xyz="0.0083307 0 0" rpy="1.5708 0 0" />
    <parent link="l_f_link1_1" />
    <child link="l_f_link1_2" />
    <axis xyz="0 0 1" />
    <limit lower="0" upper="1.3" effort="10" velocity="1.5" />
    <joint_properties damping="0.3" friction="0.6" />
  </joint>
  <link name="l_f_link1_3">
    <inertial>
      <origin xyz="0.01345865179668865 -0.0006994150593582686 0.0012931294602007472" rpy="0 0 0" />
      <mass value="0.004572753893586383" />
      <inertia ixx="2.5463017988958933e-10" ixy="1.1144061820998011e-11" ixz="5.1174127730317246e-14" iyy="4.44988993915045e-10" iyz="6.442437907835902e-15" izz="4.746572381428149e-10" />
    </inertial>
    <visual>
      <origin xyz="0 0 0" rpy="0 0 0" />
      <geometry>
        <mesh filename="../meshes/dexhand021_simplified/l_f_link1_3.STL" />
      </geometry>
      <material name="">
        <color rgba="0.6 0.6 0.6 1" />
      </material>
    </visual>
    <collision>
      <origin xyz="0 0 0" rpy="0 0 0" />
      <geometry>
        <mesh filename="../meshes/dexhand021_simplified/l_f_link1_3.STL" />
      </geometry>
    </collision>
  </link>
  <joint name="l_f_joint1_3" type="revolute">
    <origin xyz="0.043 0 0" rpy="0 0 0" />
    <parent link="l_f_link1_2" />
    <child link="l_f_link1_3" />
    <axis xyz="0 0 1" />
    <limit lower="0" upper="1.3" effort="10" velocity="1.5" />
    <joint_properties damping="0.3" friction="0.6" />
  </joint>
  <link name="l_f_link1_4">
    <inertial>
      <origin xyz="0.016260909769710546 -0.0036964901321542014 0.0012930819349579075" rpy="0 0 0" />
      <mass value="0.0061582385243810385" />
      <inertia ixx="4.011086883379703e-10" ixy="1.5555987284144313e-10" ixz="-8.579491915362132e-14" iyy="9.263594296293365e-10" iyz="2.0035549064949704e-14" izz="9.186938120322902e-10" />
    </inertial>
    <visual>
      <origin xyz="0 0 0" rpy="0 0 0" />
      <geometry>
        <mesh filename="../meshes/dexhand021_simplified/l_f_link1_4.STL" />
      </geometry>
      <material name="">
        <color rgba="0.6 0.6 0.6 1" />
      </material>
    </visual>
    <collision>
      <origin xyz="0 0 0" rpy="0 0 0" />
      <geometry>
        <mesh filename="../meshes/dexhand021_simplified/l_f_link1_4.STL" />
      </geometry>
    </collision>
  </link>
  <joint name="l_f_joint1_4" type="revolute">
    <origin xyz="0.025 0 0" rpy="0 0 0" />
    <parent link="l_f_link1_3" />
    <child link="l_f_link1_4" />
    <axis xyz="0 0 1" />
    <limit lower="0" upper="1.3" effort="10" velocity="1.5" />
    <joint_properties damping="0.3" friction="0.6" />
  </joint>
  <link name="l_f_link2_1">
    <inertial>
      <origin xyz="0.007002116442824139 1.0853722106649e-07 -0.0009685598787375309" rpy="0 0 0" />
      <mass value="0.004097010287465458" />
      <inertia ixx="2.7235763206490473e-10" ixy="3.105811960100163e-15" ixz="3.3925982165646924e-11" iyy="3.9765277905771317e-10" iyz="-1.3573950510005533e-15" izz="3.2255104577090704e-10" />
    </inertial>
    <visual>
      <origin xyz="0 0 0" rpy="0 0 0" />
      <geometry>
        <mesh filename="../meshes/dexhand021_simplified/l_f_link2_1.STL" />
      </geometry>
      <material name="">
        <color rgba="0.792156862745098 0.819607843137255 0.933333333333333 1" />
      </material>
    </visual>
    <collision>
      <origin xyz="0 0 0" rpy="0 0 0" />
      <geometry>
        <mesh filename="../meshes/dexhand021_simplified/l_f_link2_1.STL" />
      </geometry>
    </collision>
  </link>
  <joint name="l_f_joint2_1" type="revolute">
    <origin xyz="0.006966 -0.034912 0.1644" rpy="3.1416 -1.5708 0" />
    <parent link="left_hand_base" />
    <child link="l_f_link2_1" />
    <axis xyz="0 0 1" />
    <limit lower="0" upper="0.6" effort="10" velocity="1.5" />
    <joint_properties damping="0.3" friction="0.6" />
  </joint>
  <link name="l_f_link2_2">
    <inertial>
      <origin xyz="0.021162223969675573 -0.0005903778748454669 2.726223716673e-06" rpy="0 0 0" />
      <mass value="0.009428301114189446" />
      <inertia ixx="6.935853771803929e-10" ixy="3.0680508373708e-11" ixz="1.7881750565536037e-12" iyy="2.0715784629560695e-09" iyz="1.5938757167836154e-13" izz="2.0541639196537608e-09" />
    </inertial>
    <visual>
      <origin xyz="0 0 0" rpy="0 0 0" />
      <geometry>
        <mesh filename="../meshes/dexhand021_simplified/l_f_link2_2.STL" />
      </geometry>
      <material name="">
        <color rgba="0.6 0.6 0.6 1" />
      </material>
    </visual>
    <collision>
      <origin xyz="0 0 0" rpy="0 0 0" />
      <geometry>
        <mesh filename="../meshes/dexhand021_simplified/l_f_link2_2.STL" />
      </geometry>
    </collision>
  </link>
  <joint name="l_f_joint2_2" type="revolute">
    <origin xyz="0.017 0 0" rpy="1.5708 0 0" />
    <parent link="l_f_link2_1" />
    <child link="l_f_link2_2" />
    <axis xyz="0 0 1" />
    <limit lower="0" upper="1.3" effort="10" velocity="1.5" />
    <joint_properties damping="0.3" friction="0.6" />
  </joint>
  <link name="l_f_link2_3">
    <inertial>
      <origin xyz="0.01345865180416245 -0.0006994150597509925 7.128934054612281e-07" rpy="0 0 0" />
      <mass value="0.004572753788929435" />
      <inertia ixx="2.5463016843741603e-10" ixy="1.1144061675067492e-11" ixz="5.117217831792685e-14" iyy="4.449889793273617e-10" iyz="6.4425181583782644e-15" izz="4.746572278479283e-10" />
    </inertial>
    <visual>
      <origin xyz="0 0 0" rpy="0 0 0" />
      <geometry>
        <mesh filename="../meshes/dexhand021_simplified/l_f_link2_3.STL" />
      </geometry>
      <material name="">
        <color rgba="0.6 0.6 0.6 1" />
      </material>
    </visual>
    <collision>
      <origin xyz="0 0 0" rpy="0 0 0" />
      <geometry>
        <mesh filename="../meshes/dexhand021_simplified/l_f_link2_3.STL" />
      </geometry>
    </collision>
  </link>
  <joint name="l_f_joint2_3" type="revolute">
    <origin xyz="0.043 0 0" rpy="0 0 0" />
    <parent link="l_f_link2_2" />
    <child link="l_f_link2_3" />
    <axis xyz="0 0 1" />
    <limit lower="0" upper="1.3" effort="10" velocity="1.5" />
    <joint_properties damping="0.3" friction="0.6" />
  </joint>
  <link name="l_f_link2_4">
    <inertial>
      <origin xyz="0.01626090969844342 -0.0036964901152251304 7.154849544654132e-07" rpy="0 0 0" />
      <mass value="0.00615823855422499" />
      <inertia ixx="4.011081796762234e-10" ixy="1.5555987405558141e-10" ixz="-8.68132658715712e-14" iyy="9.263589275269153e-10" iyz="1.8604883999784223e-14" izz="9.186938200391148e-10" />
    </inertial>
    <visual>
      <origin xyz="0 0 0" rpy="0 0 0" />
      <geometry>
        <mesh filename="../meshes/dexhand021_simplified/l_f_link2_4.STL" />
      </geometry>
      <material name="">
        <color rgba="0.6 0.6 0.6 1" />
      </material>
    </visual>
    <collision>
      <origin xyz="0 0 0" rpy="0 0 0" />
      <geometry>
        <mesh filename="../meshes/dexhand021_simplified/l_f_link2_4.STL" />
      </geometry>
    </collision>
  </link>
  <joint name="l_f_joint2_4" type="revolute">
    <origin xyz="0.025 0 0" rpy="0 0 0" />
    <parent link="l_f_link2_3" />
    <child link="l_f_link2_4" />
    <axis xyz="0 0 1" />
    <limit lower="0" upper="1.3" effort="10" velocity="1.5" />
    <joint_properties damping="0.3" friction="0.6" />
  </joint>
  <link name="l_f_link3_1">
    <inertial>
      <origin xyz="0.00700211979781371 1.0746859203037946e-07 -0.0009685567474136043" rpy="0 0 0" />
      <mass value="0.004097008090990198" />
      <inertia ixx="2.723575329673652e-10" ixy="3.0707908274757897e-15" ixz="3.3926082584924045e-11" iyy="3.976525779519745e-10" iyz="-1.4016365237660745e-15" izz="3.225509300539399e-10" />
    </inertial>
    <visual>
      <origin xyz="0 0 0" rpy="0 0 0" />
      <geometry>
        <mesh filename="../meshes/dexhand021_simplified/l_f_link3_1.STL" />
      </geometry>
      <material name="">
        <color rgba="0.792156862745098 0.819607843137255 0.933333333333333 1" />
      </material>
    </visual>
    <collision>
      <origin xyz="0 0 0" rpy="0 0 0" />
      <geometry>
        <mesh filename="../meshes/dexhand021_simplified/l_f_link3_1.STL" />
      </geometry>
    </collision>
  </link>
  <joint name="l_f_joint3_1" type="revolute">
    <origin xyz="0.006966 -0.010612 0.1734" rpy="3.1416 -1.5708 0" />
    <parent link="left_hand_base" />
    <child link="l_f_link3_1" />
    <axis xyz="0 0 1" />
    <limit lower="-0.001" upper="0.001" effort="10" velocity="1.5" />
    <joint_properties damping="0.3" friction="0.6" />
  </joint>
  <link name="l_f_link3_2">
    <inertial>
      <origin xyz="0.021162223969675573 -0.0005903778748454669 2.7262237166728596e-06" rpy="0 0 0" />
      <mass value="0.009428301114189446" />
      <inertia ixx="6.93585377180393e-10" ixy="3.068050837370795e-11" ixz="1.7881750565535686e-12" iyy="2.0715784629560695e-09" iyz="1.5938757167836598e-13" izz="2.0541639196537608e-09" />
    </inertial>
    <visual>
      <origin xyz="0 0 0" rpy="0 0 0" />
      <geometry>
        <mesh filename="../meshes/dexhand021_simplified/l_f_link3_2.STL" />
      </geometry>
      <material name="">
        <color rgba="0.6 0.6 0.6 1" />
      </material>
    </visual>
    <collision>
      <origin xyz="0 0 0" rpy="0 0 0" />
      <geometry>
        <mesh filename="../meshes/dexhand021_simplified/l_f_link3_2.STL" />
      </geometry>
    </collision>
  </link>
  <joint name="l_f_joint3_2" type="revolute">
    <origin xyz="0.017 0 0" rpy="1.5708 0 0" />
    <parent link="l_f_link3_1" />
    <child link="l_f_link3_2" />
    <axis xyz="0 0 1" />
    <limit lower="0" upper="1.3" effort="10" velocity="1.5" />
    <joint_properties damping="0.3" friction="0.6" />
  </joint>
  <link name="l_f_link3_3">
    <inertial>
      <origin xyz="0.013458651804082164 -0.0006994150594313945 7.128935894338023e-07" rpy="0 0 0" />
      <mass value="0.004572753789108405" />
      <inertia ixx="2.546301684652061e-10" ixy="1.114406167828454e-11" ixz="5.117217957884416e-14" iyy="4.4498897934100706e-10" iyz="6.442508465568869e-15" izz="4.746572278648683e-10" />
    </inertial>
    <visual>
      <origin xyz="0 0 0" rpy="0 0 0" />
      <geometry>
        <mesh filename="../meshes/dexhand021_simplified/l_f_link3_3.STL" />
      </geometry>
      <material name="">
        <color rgba="0.6 0.6 0.6 1" />
      </material>
    </visual>
    <collision>
      <origin xyz="0 0 0" rpy="0 0 0" />
      <geometry>
        <mesh filename="../meshes/dexhand021_simplified/l_f_link3_3.STL" />
      </geometry>
    </collision>
  </link>
  <joint name="l_f_joint3_3" type="revolute">
    <origin xyz="0.043 0 0" rpy="0 0 0" />
    <parent link="l_f_link3_2" />
    <child link="l_f_link3_3" />
    <axis xyz="0 0 1" />
    <limit lower="0" upper="1.3" effort="10" velocity="1.5" />
    <joint_properties damping="0.3" friction="0.6" />
  </joint>
  <link name="l_f_link3_4">
    <inertial>
      <origin xyz="0.01626090969844342 -0.0036964901152251304 7.154849544653147e-07" rpy="0 0 0" />
      <mass value="0.00615823855422499" />
      <inertia ixx="4.011081796762234e-10" ixy="1.555598740555813e-10" ixz="-8.681326587161194e-14" iyy="9.263589275269153e-10" iyz="1.860488399977841e-14" izz="9.186938200391148e-10" />
    </inertial>
    <visual>
      <origin xyz="0 0 0" rpy="0 0 0" />
      <geometry>
        <mesh filename="../meshes/dexhand021_simplified/l_f_link3_4.STL" />
      </geometry>
      <material name="">
        <color rgba="0.6 0.6 0.6 1" />
      </material>
    </visual>
    <collision>
      <origin xyz="0 0 0" rpy="0 0 0" />
      <geometry>
        <mesh filename="../meshes/dexhand021_simplified/l_f_link3_4.STL" />
      </geometry>
    </collision>
  </link>
  <joint name="l_f_joint3_4" type="revolute">
    <origin xyz="0.025 0 0" rpy="0 0 0" />
    <parent link="l_f_link3_3" />
    <child link="l_f_link3_4" />
    <axis xyz="0 0 1" />
    <limit lower="0" upper="1.3" effort="10" velocity="1.5" />
    <joint_properties damping="0.3" friction="0.6" />
  </joint>
  <link name="l_f_link4_1">
    <inertial>
      <origin xyz="0.007002118635297736 -1.074867170048048e-07 0.0009685578821514235" rpy="0 0 0" />
      <mass value="0.004097008849009738" />
      <inertia ixx="2.7235757119377533e-10" ixy="-3.0715364786348715e-15" ixz="-3.3926045988031e-11" iyy="3.9765265119677777e-10" iyz="-1.4008169220723689e-15" izz="3.2255096997947513e-10" />
    </inertial>
    <visual>
      <origin xyz="0 0 0" rpy="0 0 0" />
      <geometry>
        <mesh filename="../meshes/dexhand021_simplified/l_f_link4_1.STL" />
      </geometry>
      <material name="">
        <color rgba="0.792156862745098 0.819607843137255 0.933333333333333 1" />
      </material>
    </visual>
    <collision>
      <origin xyz="0 0 0" rpy="0 0 0" />
      <geometry>
        <mesh filename="../meshes/dexhand021_simplified/l_f_link4_1.STL" />
      </geometry>
    </collision>
  </link>
  <joint name="l_f_joint4_1" type="revolute">
    <origin xyz="0.006966 0.013688 0.1644" rpy="0 -1.5708 0" />
    <parent link="left_hand_base" />
    <child link="l_f_link4_1" />
    <axis xyz="0 0 1" />
    <limit lower="0" upper="0.6" effort="10" velocity="1.5" />
    <joint_properties damping="0.3" friction="0.6" />
  </joint>
  <link name="l_f_link4_2">
    <inertial>
      <origin xyz="0.02116222396967557 -0.0005903778748454666 2.726223716673e-06" rpy="0 0 0" />
      <mass value="0.009428301114189446" />
      <inertia ixx="6.935853771803929e-10" ixy="3.0680508373708103e-11" ixz="1.7881750565536035e-12" iyy="2.071578462956071e-09" iyz="1.5938757167836672e-13" izz="2.0541639196537616e-09" />
    </inertial>
    <visual>
      <origin xyz="0 0 0" rpy="0 0 0" />
      <geometry>
        <mesh filename="../meshes/dexhand021_simplified/l_f_link4_2.STL" />
      </geometry>
      <material name="">
        <color rgba="0.6 0.6 0.6 1" />
      </material>
    </visual>
    <collision>
      <origin xyz="0 0 0" rpy="0 0 0" />
      <geometry>
        <mesh filename="../meshes/dexhand021_simplified/l_f_link4_2.STL" />
      </geometry>
    </collision>
  </link>
  <joint name="l_f_joint4_2" type="revolute">
    <origin xyz="0.017 0 0" rpy="-1.5708 0 0" />
    <parent link="l_f_link4_1" />
    <child link="l_f_link4_2" />
    <axis xyz="0 0 1" />
    <limit lower="0" upper="1.3" effort="10" velocity="1.5" />
    <joint_properties damping="0.3" friction="0.6" />
  </joint>
  <link name="l_f_link4_3">
    <inertial>
      <origin xyz="0.013458651804175747 -0.0006994150597613606 7.128935762079505e-07" rpy="0 0 0" />
      <mass value="0.004572753788921786" />
      <inertia ixx="2.546301684362594e-10" ixy="1.114406167462815e-11" ixz="5.1172182207921757e-14" iyy="4.44988979326166e-10" iyz="6.442512730790462e-15" izz="4.746572278471702e-10" />
    </inertial>
    <visual>
      <origin xyz="0 0 0" rpy="0 0 0" />
      <geometry>
        <mesh filename="../meshes/dexhand021_simplified/l_f_link4_3.STL" />
      </geometry>
      <material name="">
        <color rgba="0.6 0.6 0.6 1" />
      </material>
    </visual>
    <collision>
      <origin xyz="0 0 0" rpy="0 0 0" />
      <geometry>
        <mesh filename="../meshes/dexhand021_simplified/l_f_link4_3.STL" />
      </geometry>
    </collision>
  </link>
  <joint name="l_f_joint4_3" type="revolute">
    <origin xyz="0.043 0 0" rpy="0 0 0" />
    <parent link="l_f_link4_2" />
    <child link="l_f_link4_3" />
    <axis xyz="0 0 1" />
    <limit lower="0" upper="1.3" effort="10" velocity="1.5" />
    <joint_properties damping="0.3" friction="0.6" />
  </joint>
  <link name="l_f_link4_4">
    <inertial>
      <origin xyz="0.016260909698443425 -0.0036964901152251304 7.154849544656191e-07" rpy="0 0 0" />
      <mass value="0.00615823855422499" />
      <inertia ixx="4.011081796762233e-10" ixy="1.555598740555813e-10" ixz="-8.681326587154369e-14" iyy="9.263589275269145e-10" iyz="1.8604883999770175e-14" izz="9.18693820039114e-10" />
    </inertial>
    <visual>
      <origin xyz="0 0 0" rpy="0 0 0" />
      <geometry>
        <mesh filename="../meshes/dexhand021_simplified/l_f_link4_4.STL" />
      </geometry>
      <material name="">
        <color rgba="0.6 0.6 0.6 1" />
      </material>
    </visual>
    <collision>
      <origin xyz="0 0 0" rpy="0 0 0" />
      <geometry>
        <mesh filename="../meshes/dexhand021_simplified/l_f_link4_4.STL" />
      </geometry>
    </collision>
  </link>
  <joint name="l_f_joint4_4" type="revolute">
    <origin xyz="0.025 0 0" rpy="0 0 0" />
    <parent link="l_f_link4_3" />
    <child link="l_f_link4_4" />
    <axis xyz="0 0 1" />
    <limit lower="0" upper="1.3" effort="10" velocity="1.5" />
    <joint_properties damping="0.3" friction="0.6" />
  </joint>
  <link name="l_f_link5_1">
    <inertial>
      <origin xyz="0.007002122699750756 -1.0891508955913684e-07 0.0009685510768750549" rpy="0 0 0" />
      <mass value="0.004097005770491854" />
      <inertia ixx="2.723572534904412e-10" ixy="-3.119786929089952e-15" ixz="-3.3926236911239105e-11" iyy="3.9765223612050723e-10" iyz="-1.3416687183467564e-15" izz="3.225508590514057e-10" />
    </inertial>
    <visual>
      <origin xyz="0 0 0" rpy="0 0 0" />
      <geometry>
        <mesh filename="../meshes/dexhand021_simplified/l_f_link5_1.STL" />
      </geometry>
      <material name="">
        <color rgba="0.792156862745098 0.819607843137255 0.933333333333333 1" />
      </material>
    </visual>
    <collision>
      <origin xyz="0 0 0" rpy="0 0 0" />
      <geometry>
        <mesh filename="../meshes/dexhand021_simplified/l_f_link5_1.STL" />
      </geometry>
    </collision>
  </link>
  <joint name="l_f_joint5_1" type="revolute">
    <origin xyz="0.006966 0.037988 0.1504" rpy="0 -1.5708 0" />
    <parent link="left_hand_base" />
    <child link="l_f_link5_1" />
    <axis xyz="0 0 1" />
    <limit lower="0" upper="0.6" effort="10" velocity="1.5" />
    <joint_properties damping="0.3" friction="0.6" />
  </joint>
  <link name="l_f_link5_2">
    <inertial>
      <origin xyz="0.02116222396967557 -0.0005903778748454669 2.72622371667293e-06" rpy="0 0 0" />
      <mass value="0.009428301114189446" />
      <inertia ixx="6.93585377180393e-10" ixy="3.0680508373707897e-11" ixz="1.788175056553524e-12" iyy="2.071578462956071e-09" iyz="1.5938757167836677e-13" izz="2.0541639196537616e-09" />
    </inertial>
    <visual>
      <origin xyz="0 0 0" rpy="0 0 0" />
      <geometry>
        <mesh filename="../meshes/dexhand021_simplified/l_f_link5_2.STL" />
      </geometry>
      <material name="">
        <color rgba="0.6 0.6 0.6 1" />
      </material>
    </visual>
    <collision>
      <origin xyz="0 0 0" rpy="0 0 0" />
      <geometry>
        <mesh filename="../meshes/dexhand021_simplified/l_f_link5_2.STL" />
      </geometry>
    </collision>
  </link>
  <joint name="l_f_joint5_2" type="revolute">
    <origin xyz="0.017 0 0" rpy="-1.5708 0 0" />
    <parent link="l_f_link5_1" />
    <child link="l_f_link5_2" />
    <axis xyz="0 0 1" />
    <limit lower="0" upper="1.3" effort="10" velocity="1.5" />
    <joint_properties damping="0.3" friction="0.6" />
  </joint>
  <link name="l_f_link5_3">
    <inertial>
      <origin xyz="0.013458651804125232 -0.0006994150597455533 7.128935022369632e-07" rpy="0 0 0" />
      <mass value="0.004572753788933973" />
      <inertia ixx="2.546301684380226e-10" ixy="1.1144061676265612e-11" ixz="5.117217899456576e-14" iyy="4.449889793282455e-10" iyz="6.442515046640594e-15" izz="4.746572278485528e-10" />
    </inertial>
    <visual>
      <origin xyz="0 0 0" rpy="0 0 0" />
      <geometry>
        <mesh filename="../meshes/dexhand021_simplified/l_f_link5_3.STL" />
      </geometry>
      <material name="">
        <color rgba="0.6 0.6 0.6 1" />
      </material>
    </visual>
    <collision>
      <origin xyz="0 0 0" rpy="0 0 0" />
      <geometry>
        <mesh filename="../meshes/dexhand021_simplified/l_f_link5_3.STL" />
      </geometry>
    </collision>
  </link>
  <joint name="l_f_joint5_3" type="revolute">
    <origin xyz="0.043 0 0" rpy="0 0 0" />
    <parent link="l_f_link5_2" />
    <child link="l_f_link5_3" />
    <axis xyz="0 0 1" />
    <limit lower="0" upper="1.3" effort="10" velocity="1.5" />
    <joint_properties damping="0.3" friction="0.6" />
  </joint>
  <link name="l_f_link5_4">
    <inertial>
      <origin xyz="0.01626090969844342 -0.003696490115225131 7.154849544654222e-07" rpy="0 0 0" />
      <mass value="0.00615823855422499" />
      <inertia ixx="4.0110817967622324e-10" ixy="1.5555987405558126e-10" ixz="-8.681326587158558e-14" iyy="9.263589275269153e-10" iyz="1.8604883999773192e-14" izz="9.186938200391148e-10" />
    </inertial>
    <visual>
      <origin xyz="0 0 0" rpy="0 0 0" />
      <geometry>
        <mesh filename="../meshes/dexhand021_simplified/l_f_link5_4.STL" />
      </geometry>
      <material name="">
        <color rgba="0.6 0.6 0.6 1" />
      </material>
    </visual>
    <collision>
      <origin xyz="0 0 0" rpy="0 0 0" />
      <geometry>
        <mesh filename="../meshes/dexhand021_simplified/l_f_link5_4.STL" />
      </geometry>
    </collision>
  </link>
  <joint name="l_f_joint5_4" type="revolute">
    <origin xyz="0.025 0 0" rpy="0 0 0" />
    <parent link="l_f_link5_3" />
    <child link="l_f_link5_4" />
    <axis xyz="0 0 1" />
    <limit lower="0" upper="1.3" effort="10" velocity="1.5" />
    <joint_properties damping="0.3" friction="0.6" />
  </joint>


  <link name="l_f_link1_tip">
    <inertial>
      <origin xyz="0 0 0.005" rpy="0 0 0" />
      <mass value="0.001" />
      <inertia ixx="1.0E-09" ixy="0.0" ixz="0.0" iyy="1.0E-09" iyz="0.0" izz="1.0E-09" />
    </inertial>
    <visual>
      <origin xyz="0.015 -0.004 0" rpy="0 0 0" />
      <geometry>
        <sphere radius="0.002" />
      </geometry>
      <material name="">
        <color rgba="1 0 0 1" />
      </material>
    </visual>
    <collision>
      <origin xyz="0 0 0" rpy="0 0 0" />
      <geometry>
        <sphere radius="0.002" />
      </geometry>
    </collision>
  </link>

  <joint name="l_f_joint1_tip" type="fixed">
    <origin xyz="0.02 0 0" rpy="0 0 0" />
    <parent link="l_f_link1_4" />
    <child link="l_f_link1_tip" />
  </joint>

  <link name="l_f_link2_tip">
    <inertial>
      <origin xyz="0 0 0.005" rpy="0 0 0" />
      <mass value="0.001" />
      <inertia ixx="1.0E-09" ixy="0.0" ixz="0.0" iyy="1.0E-09" iyz="0.0" izz="1.0E-09" />
    </inertial>
    <visual>
      <origin xyz="0.015 -0.004 0" rpy="0 0 0" />
      <geometry>
        <sphere radius="0.002" />
      </geometry>
      <material name="">
        <color rgba="1 0 0 1" />
      </material>
    </visual>
    <collision>
      <origin xyz="0 0 0" rpy="0 0 0" />
      <geometry>
        <sphere radius="0.002" />
      </geometry>
    </collision>
  </link>

  <joint name="l_f_joint2_tip" type="fixed">
    <origin xyz="0.02 0 0" rpy="0 0 0" />
    <parent link="l_f_link2_4" />
    <child link="l_f_link2_tip" />
  </joint>

  <link name="l_f_link3_tip">
    <inertial>
      <origin xyz="0 0 0.005" rpy="0 0 0" />
      <mass value="0.001" />
      <inertia ixx="1.0E-09" ixy="0.0" ixz="0.0" iyy="1.0E-09" iyz="0.0" izz="1.0E-09" />
    </inertial>
    <visual>
      <origin xyz="0.015 -0.004 0" rpy="0 0 0" />
      <geometry>
        <sphere radius="0.002" />
      </geometry>
      <material name="">
        <color rgba="1 0 0 1" />
      </material>
    </visual>
    <collision>
      <origin xyz="0 0 0" rpy="0 0 0" />
      <geometry>
        <sphere radius="0.002" />
      </geometry>
    </collision>
  </link>

  <joint name="l_f_joint3_tip" type="fixed">
    <origin xyz="0.02 0 0" rpy="0 0 0" />
    <parent link="l_f_link3_4" />
    <child link="l_f_link3_tip" />
  </joint>

  <link name="l_f_link4_tip">
    <inertial>
      <origin xyz="0 0 0.005" rpy="0 0 0" />
      <mass value="0.001" />
      <inertia ixx="1.0E-09" ixy="0.0" ixz="0.0" iyy="1.0E-09" iyz="0.0" izz="1.0E-09" />
    </inertial>
    <visual>
      <origin xyz="0.015 -0.004 0" rpy="0 0 0" />
      <geometry>
        <sphere radius="0.002" />
      </geometry>
      <material name="">
        <color rgba="1 0 0 1" />
      </material>
    </visual>
    <collision>
      <origin xyz="0 0 0" rpy="0 0 0" />
      <geometry>
        <sphere radius="0.002" />
      </geometry>
    </collision>
  </link>

  <joint name="l_f_joint4_tip" type="fixed">
    <origin xyz="0.02 0 0" rpy="0 0 0" />
    <parent link="l_f_link4_4" />
    <child link="l_f_link4_tip" />
  </joint>

  <link name="l_f_link5_tip">
    <inertial>
      <origin xyz="0 0 0.005" rpy="0 0 0" />
      <mass value="0.001" />
      <inertia ixx="1.0E-09" ixy="0.0" ixz="0.0" iyy="1.0E-09" iyz="0.0" izz="1.0E-09" />
    </inertial>
    <visual>
      <origin xyz="0.015 -0.004 0" rpy="0 0 0" />
      <geometry>
        <sphere radius="0.002" />
      </geometry>
      <material name="">
        <color rgba="1 0 0 1" />
      </material>
    </visual>
    <collision>
      <origin xyz="0 0 0" rpy="0 0 0" />
      <geometry>
        <sphere radius="0.002" />
      </geometry>
    </collision>
  </link>

  <joint name="l_f_joint5_tip" type="fixed">
    <origin xyz="0.02 0 0" rpy="0 0 0" />
    <parent link="l_f_link5_4" />
    <child link="l_f_link5_tip" />
  </joint>
</robot>
