<?xml version="1.0" encoding="utf-8"?>

<robot
  name="dexhand021_right_simplified">

  <mujoco>
    <compiler meshdir="../meshes/dexhand021_simplified/" balanceinertia="true" discardvisual="false" />
  </mujoco>

  <link
    name="right_hand_base">
    <inertial>
      <origin
        xyz="-0.015115 -4.2747E-05 0.09592"
        rpy="0 0 0" />
      <mass
        value="0.39703" />
      <inertia
        ixx="0.00094823"
        ixy="-6.3469E-07"
        ixz="8.5392E-06"
        iyy="0.00062806"
        iyz="-6.0165E-06"
        izz="0.00036751" />
    </inertial>
    <visual>
      <origin
        xyz="0 0 0"
        rpy="0 0 0" />
      <geometry>
        <mesh
          filename="../meshes/right_hand_base.STL" />
      </geometry>
      <material
        name="">
        <color
          rgba="0.75294 0.75294 0.75294 1" />
      </material>
    </visual>
    <collision>
      <origin
        xyz="0 0 0"
        rpy="0 0 0" />
      <geometry>
        <mesh
          filename="../meshes/right_hand_base.STL" />
      </geometry>
    </collision>
  </link>
  <link
    name="r_f_link1_1">
    <inertial>
      <origin
        xyz="0.0019855 -0.00034962 0.013484"
        rpy="0 0 0" />
      <mass
        value="0.0055264" />
      <inertia
        ixx="4.7024E-07"
        ixy="4.4475E-09"
        ixz="4.1608E-08"
        iyy="5.5184E-07"
        iyz="-1.0825E-08"
        izz="2.563E-07" />
    </inertial>
    <visual>
      <origin
        xyz="0 0 0"
        rpy="0 0 0" />
      <geometry>
        <mesh
          filename="../meshes/r_f_link1_1.STL" />
      </geometry>
      <material
        name="">
        <color
          rgba="0.6 0.6 0.6 1" />
      </material>
    </visual>
    <collision>
      <origin
        xyz="0 0 0"
        rpy="0 0 0" />
      <geometry>
        <mesh
          filename="../meshes/r_f_link1_1.STL" />
      </geometry>
    </collision>
  </link>
  <joint
    name="r_f_joint1_1"
    type="revolute">
    <origin
      xyz="0.032783 0.023781 0.11211"
      rpy="-2.8732 -0.15197 1.3168" />
    <parent
      link="right_hand_base" />
    <child
      link="r_f_link1_1" />
    <axis
      xyz="0 0 1" />
    <limit lower="0" upper="2.2" effort="10" velocity="1.5" />
    <joint_properties damping="0.3" friction="0.5" />
  </joint>
  <link
    name="r_f_link1_2">
    <inertial>
      <origin
        xyz="0.021437 0.00017315 -0.0012982"
        rpy="0 0 0" />
      <mass
        value="0.012462" />
      <inertia
        ixx="7.7858E-07"
        ixy="5.4485E-08"
        ixz="-1.5949E-09"
        iyy="2.0749E-06"
        iyz="-3.3573E-10"
        izz="2.145E-06" />
    </inertial>
    <visual>
      <origin
        xyz="0 0 0"
        rpy="0 0 0" />
      <geometry>
        <mesh
          filename="../meshes/r_f_link1_2.STL" />
      </geometry>
      <material
        name="">
        <color
          rgba="0.6 0.6 0.6 1" />
      </material>
    </visual>
    <collision>
      <origin
        xyz="0 0 0"
        rpy="0 0 0" />
      <geometry>
        <mesh
          filename="../meshes/r_f_link1_2.STL" />
      </geometry>
    </collision>
  </link>
  <joint
    name="r_f_joint1_2"
    type="revolute">
    <origin
      xyz="0.0083307 0 0"
      rpy="-1.5708 0 0" />
    <parent
      link="r_f_link1_1" />
    <child
      link="r_f_link1_2" />
    <axis
      xyz="0 0 1" />
    <limit lower="0" upper="1.3" effort="10" velocity="1.5" />
    <joint_properties damping="0.3" friction="0.5" />
  </joint>
  <link
    name="r_f_link1_3">
    <inertial>
      <origin
        xyz="0.013455 -0.00070242 -0.0012928"
        rpy="0 0 0" />
      <mass
        value="0.005726" />
      <inertia
        ixx="2.5543E-07"
        ixy="1.1107E-08"
        ixz="-1.782E-11"
        iyy="4.4684E-07"
        iyz="1.2469E-13"
        izz="4.7655E-07" />
    </inertial>
    <visual>
      <origin
        xyz="0 0 0"
        rpy="0 0 0" />
      <geometry>
        <mesh
          filename="../meshes/r_f_link1_3.STL" />
      </geometry>
      <material
        name="">
        <color
          rgba="0.6 0.6 0.6 1" />
      </material>
    </visual>
    <collision>
      <origin
        xyz="0 0 0"
        rpy="0 0 0" />
      <geometry>
        <mesh
          filename="../meshes/r_f_link1_3.STL" />
      </geometry>
    </collision>
  </link>
  <joint
    name="r_f_joint1_3"
    type="revolute">
    <origin
      xyz="0.043 0 0"
      rpy="0 0 0" />
    <parent
      link="r_f_link1_2" />
    <child
      link="r_f_link1_3" />
    <axis
      xyz="0 0 1" />
    <limit lower="0" upper="1.3" effort="10" velocity="1.5" />
    <joint_properties damping="0.3" friction="0.5" />
  </joint>
  <link
    name="r_f_link1_4">
    <inertial>
      <origin
        xyz="-0.10671 -0.0011814 -0.035828"
        rpy="0 0 0" />
      <mass
        value="0.0051136" />
      <inertia
        ixx="0.001731"
        ixy="-0.00020231"
        ixz="7.0546E-05"
        iyy="0.00069416"
        iyz="0.00027029"
        izz="0.0021193" />
    </inertial>
    <visual>
      <origin
        xyz="0 0 0"
        rpy="0 0 0" />
      <geometry>
        <mesh
          filename="../meshes/r_f_link1_4.STL" />
      </geometry>
      <material
        name="">
        <color
          rgba="0.6 0.6 0.6 1" />
      </material>
    </visual>
    <collision>
      <origin
        xyz="0 0 0"
        rpy="0 0 0" />
      <geometry>
        <mesh
          filename="../meshes/r_f_link1_4.STL" />
      </geometry>
    </collision>
  </link>
  <joint
    name="r_f_joint1_4"
    type="revolute">
    <origin
      xyz="0.025 0 0"
      rpy="0 0 0" />
    <parent
      link="r_f_link1_3" />
    <child
      link="r_f_link1_4" />
    <axis
      xyz="0 0 1" />
    <limit lower="0" upper="1.3" effort="10" velocity="1.5" />
    <joint_properties damping="0.3" friction="0.5" />
  </joint>
  <link
    name="r_f_link2_1">
    <inertial>
      <origin
        xyz="0.007003 2.619E-09 0.00096933"
        rpy="0 0 0" />
      <mass
        value="0.0051273" />
      <inertia
        ixx="2.7296E-07"
        ixy="2.1846E-13"
        ixz="-3.3975E-08"
        iyy="3.9879E-07"
        iyz="8.6762E-13"
        izz="3.2351E-07" />
    </inertial>
    <visual>
      <origin
        xyz="0 0 0"
        rpy="0 0 0" />
      <geometry>
        <mesh
          filename="../meshes/r_f_link2_1.STL" />
      </geometry>
      <material
        name="">
        <color
          rgba="0.79216 0.81961 0.93333 1" />
      </material>
    </visual>
    <collision>
      <origin
        xyz="0 0 0"
        rpy="0 0 0" />
      <geometry>
        <mesh
          filename="../meshes/r_f_link2_1.STL" />
      </geometry>
    </collision>
  </link>
  <joint
    name="r_f_joint2_1"
    type="revolute">
    <origin
      xyz="0.006966 0.034912 0.1644"
      rpy="0 -1.5708 0" />
    <parent
      link="right_hand_base" />
    <child
      link="r_f_link2_1" />
    <axis
      xyz="0 0 1" />
    <limit lower="0" upper="0.6" effort="10" velocity="1.5" />
    <joint_properties damping="0.3" friction="0.5" />
  </joint>
  <link
    name="r_f_link2_2">
    <inertial>
      <origin
        xyz="0.02116 -0.00059146 -2.1984E-06"
        rpy="0 0 0" />
      <mass
        value="0.011802" />
      <inertia
        ixx="6.9559E-07"
        ixy="3.0616E-08"
        ixz="-1.7958E-09"
        iyy="2.0766E-06"
        iyz="-1.0841E-10"
        izz="2.0592E-06" />
    </inertial>
    <visual>
      <origin
        xyz="0 0 0"
        rpy="0 0 0" />
      <geometry>
        <mesh
          filename="../meshes/r_f_link2_2.STL" />
      </geometry>
      <material
        name="">
        <color
          rgba="0.6 0.6 0.6 1" />
      </material>
    </visual>
    <collision>
      <origin
        xyz="0 0 0"
        rpy="0 0 0" />
      <geometry>
        <mesh
          filename="../meshes/r_f_link2_2.STL" />
      </geometry>
    </collision>
  </link>
  <joint
    name="r_f_joint2_2"
    type="revolute">
    <origin
      xyz="0.017 0 0"
      rpy="-1.5708 0 0" />
    <parent
      link="r_f_link2_1" />
    <child
      link="r_f_link2_2" />
    <axis
      xyz="0 0 1" />
    <limit lower="0" upper="1.3" effort="10" velocity="1.5" />
    <joint_properties damping="0.3" friction="0.5" />
  </joint>
  <link
    name="r_f_link2_3">
    <inertial>
      <origin
        xyz="0.013455 -0.00070241 -3.5721E-07"
        rpy="0 0 0" />
      <mass
        value="0.005726" />
      <inertia
        ixx="2.5543E-07"
        ixy="1.1107E-08"
        ixz="-1.7691E-11"
        iyy="4.4684E-07"
        iyz="-3.9336E-13"
        izz="4.7655E-07" />
    </inertial>
    <visual>
      <origin
        xyz="0 0 0"
        rpy="0 0 0" />
      <geometry>
        <mesh
          filename="../meshes/r_f_link2_3.STL" />
      </geometry>
      <material
        name="">
        <color
          rgba="0.6 0.6 0.6 1" />
      </material>
    </visual>
    <collision>
      <origin
        xyz="0 0 0"
        rpy="0 0 0" />
      <geometry>
        <mesh
          filename="../meshes/r_f_link2_3.STL" />
      </geometry>
    </collision>
  </link>
  <joint
    name="r_f_joint2_3"
    type="revolute">
    <origin
      xyz="0.043 0 0"
      rpy="0 0 0" />
    <parent
      link="r_f_link2_2" />
    <child
      link="r_f_link2_3" />
    <axis
      xyz="0 0 1" />
    <limit lower="0" upper="1.3" effort="10" velocity="1.5" />
    <joint_properties damping="0.3" friction="0.5" />
  </joint>
  <link
    name="r_f_link2_4">
    <inertial>
      <origin
        xyz="-0.13363 -0.015786 -0.032666"
        rpy="0 0 0" />
      <mass
        value="0.0051136" />
      <inertia
        ixx="0.00061681"
        ixy="-0.00013518"
        ixz="-9.4865E-06"
        iyy="0.0021495"
        iyz="-6.4212E-05"
        izz="0.0017781" />
    </inertial>
    <visual>
      <origin
        xyz="0 0 0"
        rpy="0 0 0" />
      <geometry>
        <mesh
          filename="../meshes/r_f_link2_4.STL" />
      </geometry>
      <material
        name="">
        <color
          rgba="0.6 0.6 0.6 1" />
      </material>
    </visual>
    <collision>
      <origin
        xyz="0 0 0"
        rpy="0 0 0" />
      <geometry>
        <mesh
          filename="../meshes/r_f_link2_4.STL" />
      </geometry>
    </collision>
  </link>
  <joint
    name="r_f_joint2_4"
    type="revolute">
    <origin
      xyz="0.025 0 0"
      rpy="0 0 0" />
    <parent
      link="r_f_link2_3" />
    <child
      link="r_f_link2_4" />
    <axis
      xyz="0 0 1" />
    <limit lower="0" upper="1.3" effort="10" velocity="1.5" />
    <joint_properties damping="0.3" friction="0.5" />
  </joint>
  <link
    name="r_f_link3_1">
    <inertial>
      <origin
        xyz="0.007003 2.619E-09 0.00096932"
        rpy="0 0 0" />
      <mass
        value="0.0051273" />
      <inertia
        ixx="2.7296E-07"
        ixy="2.1846E-13"
        ixz="-3.3975E-08"
        iyy="3.9879E-07"
        iyz="8.6762E-13"
        izz="3.2351E-07" />
    </inertial>
    <visual>
      <origin
        xyz="0 0 0"
        rpy="0 0 0" />
      <geometry>
        <mesh
          filename="../meshes/r_f_link3_1.STL" />
      </geometry>
      <material
        name="">
        <color
          rgba="0.79216 0.81961 0.93333 1" />
      </material>
    </visual>
    <collision>
      <origin
        xyz="0 0 0"
        rpy="0 0 0" />
      <geometry>
        <mesh
          filename="../meshes/r_f_link3_1.STL" />
      </geometry>
    </collision>
  </link>
  <joint
    name="r_f_joint3_1"
    type="revolute">
    <origin
      xyz="0.006966 0.010612 0.1734"
      rpy="0 -1.5708 0" />
    <parent
      link="right_hand_base" />
    <child
      link="r_f_link3_1" />
    <axis
      xyz="0 0 1" />
    <limit
      lower="-0.001"
      upper="0.001"
      effort="0"
      velocity="0" />
  </joint>
  <link
    name="r_f_link3_2">
    <inertial>
      <origin
        xyz="0.02116 -0.00059146 -2.1984E-06"
        rpy="0 0 0" />
      <mass
        value="0.011802" />
      <inertia
        ixx="6.9559E-07"
        ixy="3.0616E-08"
        ixz="-1.7958E-09"
        iyy="2.0766E-06"
        iyz="-1.0841E-10"
        izz="2.0592E-06" />
    </inertial>
    <visual>
      <origin
        xyz="0 0 0"
        rpy="0 0 0" />
      <geometry>
        <mesh
          filename="../meshes/r_f_link3_2.STL" />
      </geometry>
      <material
        name="">
        <color
          rgba="0.6 0.6 0.6 1" />
      </material>
    </visual>
    <collision>
      <origin
        xyz="0 0 0"
        rpy="0 0 0" />
      <geometry>
        <mesh
          filename="../meshes/r_f_link3_2.STL" />
      </geometry>
    </collision>
  </link>
  <joint
    name="r_f_joint3_2"
    type="revolute">
    <origin
      xyz="0.017 0 0"
      rpy="-1.5708 0 0" />
    <parent
      link="r_f_link3_1" />
    <child
      link="r_f_link3_2" />
    <axis
      xyz="0 0 1" />
    <limit lower="0" upper="1.3" effort="10" velocity="1.5" />
    <joint_properties damping="0.3" friction="0.5" />
  </joint>
  <link
    name="r_f_link3_3">
    <inertial>
      <origin
        xyz="0.013455 -0.00070241 -3.5721E-07"
        rpy="0 0 0" />
      <mass
        value="0.005726" />
      <inertia
        ixx="2.5543E-07"
        ixy="1.1107E-08"
        ixz="-1.7691E-11"
        iyy="4.4684E-07"
        iyz="-3.9336E-13"
        izz="4.7655E-07" />
    </inertial>
    <visual>
      <origin
        xyz="0 0 0"
        rpy="0 0 0" />
      <geometry>
        <mesh
          filename="../meshes/r_f_link3_3.STL" />
      </geometry>
      <material
        name="">
        <color
          rgba="0.6 0.6 0.6 1" />
      </material>
    </visual>
    <collision>
      <origin
        xyz="0 0 0"
        rpy="0 0 0" />
      <geometry>
        <mesh
          filename="../meshes/r_f_link3_3.STL" />
      </geometry>
    </collision>
  </link>
  <joint
    name="r_f_joint3_3"
    type="revolute">
    <origin
      xyz="0.043 0 0"
      rpy="0 0 0" />
    <parent
      link="r_f_link3_2" />
    <child
      link="r_f_link3_3" />
    <axis
      xyz="0 0 1" />
    <limit lower="0" upper="1.3" effort="10" velocity="1.5" />
    <joint_properties damping="0.3" friction="0.5" />
  </joint>
  <link
    name="r_f_link3_4">
    <inertial>
      <origin
        xyz="-0.14263 -0.015786 -0.0083656"
        rpy="0 0 0" />
      <mass
        value="0.0051136" />
      <inertia
        ixx="0.00061681"
        ixy="-0.00013518"
        ixz="-9.4865E-06"
        iyy="0.0021495"
        iyz="-6.4212E-05"
        izz="0.0017781" />
    </inertial>
    <visual>
      <origin
        xyz="0 0 0"
        rpy="0 0 0" />
      <geometry>
        <mesh
          filename="../meshes/r_f_link3_4.STL" />
      </geometry>
      <material
        name="">
        <color
          rgba="0.6 0.6 0.6 1" />
      </material>
    </visual>
    <collision>
      <origin
        xyz="0 0 0"
        rpy="0 0 0" />
      <geometry>
        <mesh
          filename="../meshes/r_f_link3_4.STL" />
      </geometry>
    </collision>
  </link>
  <joint
    name="r_f_joint3_4"
    type="revolute">
    <origin
      xyz="0.025 0 0"
      rpy="0 0 0" />
    <parent
      link="r_f_link3_3" />
    <child
      link="r_f_link3_4" />
    <axis
      xyz="0 0 1" />
    <limit lower="0" upper="1.3" effort="10" velocity="1.5" />
    <joint_properties damping="0.3" friction="0.5" />
  </joint>
  <link
    name="r_f_link4_1">
    <inertial>
      <origin
        xyz="0.007003 -2.619E-09 -0.00096933"
        rpy="0 0 0" />
      <mass
        value="0.0051273" />
      <inertia
        ixx="2.7296E-07"
        ixy="-2.1846E-13"
        ixz="3.3975E-08"
        iyy="3.9879E-07"
        iyz="8.6762E-13"
        izz="3.2351E-07" />
    </inertial>
    <visual>
      <origin
        xyz="0 0 0"
        rpy="0 0 0" />
      <geometry>
        <mesh
          filename="../meshes/r_f_link4_1.STL" />
      </geometry>
      <material
        name="">
        <color
          rgba="0.79216 0.81961 0.93333 1" />
      </material>
    </visual>
    <collision>
      <origin
        xyz="0 0 0"
        rpy="0 0 0" />
      <geometry>
        <mesh
          filename="../meshes/r_f_link4_1.STL" />
      </geometry>
    </collision>
  </link>
  <joint
    name="r_f_joint4_1"
    type="revolute">
    <origin
      xyz="0.006966 -0.013688 0.1644"
      rpy="3.1416 -1.5708 0" />
    <parent
      link="right_hand_base" />
    <child
      link="r_f_link4_1" />
    <axis
      xyz="0 0 1" />
    <limit lower="0" upper="0.6" effort="10" velocity="1.5" />
    <joint_properties damping="0.3" friction="0.5" />
  </joint>
  <link
    name="r_f_link4_2">
    <inertial>
      <origin
        xyz="0.02116 -0.00059146 -2.1984E-06"
        rpy="0 0 0" />
      <mass
        value="0.011802" />
      <inertia
        ixx="6.9559E-07"
        ixy="3.0616E-08"
        ixz="-1.7958E-09"
        iyy="2.0766E-06"
        iyz="-1.0841E-10"
        izz="2.0592E-06" />
    </inertial>
    <visual>
      <origin
        xyz="0 0 0"
        rpy="0 0 0" />
      <geometry>
        <mesh
          filename="../meshes/r_f_link4_2.STL" />
      </geometry>
      <material
        name="">
        <color
          rgba="0.6 0.6 0.6 1" />
      </material>
    </visual>
    <collision>
      <origin
        xyz="0 0 0"
        rpy="0 0 0" />
      <geometry>
        <mesh
          filename="../meshes/r_f_link4_2.STL" />
      </geometry>
    </collision>
  </link>
  <joint
    name="r_f_joint4_2"
    type="revolute">
    <origin
      xyz="0.017 0 0"
      rpy="1.5708 0 0" />
    <parent
      link="r_f_link4_1" />
    <child
      link="r_f_link4_2" />
    <axis
      xyz="0 0 1" />
    <limit lower="0" upper="1.3" effort="10" velocity="1.5" />
    <joint_properties damping="0.3" friction="0.5" />
  </joint>
  <link
    name="r_f_link4_3">
    <inertial>
      <origin
        xyz="0.013455 -0.00070241 -3.572E-07"
        rpy="0 0 0" />
      <mass
        value="0.005726" />
      <inertia
        ixx="2.5543E-07"
        ixy="1.1107E-08"
        ixz="-1.7691E-11"
        iyy="4.4684E-07"
        iyz="-3.9368E-13"
        izz="4.7655E-07" />
    </inertial>
    <visual>
      <origin
        xyz="0 0 0"
        rpy="0 0 0" />
      <geometry>
        <mesh
          filename="../meshes/r_f_link4_3.STL" />
      </geometry>
      <material
        name="">
        <color
          rgba="0.6 0.6 0.6 1" />
      </material>
    </visual>
    <collision>
      <origin
        xyz="0 0 0"
        rpy="0 0 0" />
      <geometry>
        <mesh
          filename="../meshes/r_f_link4_3.STL" />
      </geometry>
    </collision>
  </link>
  <joint
    name="r_f_joint4_3"
    type="revolute">
    <origin
      xyz="0.043 0 0"
      rpy="0 0 0" />
    <parent
      link="r_f_link4_2" />
    <child
      link="r_f_link4_3" />
    <axis
      xyz="0 0 1" />
    <limit lower="0" upper="1.3" effort="10" velocity="1.5" />
    <joint_properties damping="0.3" friction="0.5" />
  </joint>
  <link
    name="r_f_link4_4">
    <inertial>
      <origin
        xyz="-0.13363 -0.015786 0.015934"
        rpy="0 0 0" />
      <mass
        value="0.0051136" />
      <inertia
        ixx="0.00061681"
        ixy="-0.00013518"
        ixz="-9.4865E-06"
        iyy="0.0021495"
        iyz="-6.4212E-05"
        izz="0.0017781" />
    </inertial>
    <visual>
      <origin
        xyz="0 0 0"
        rpy="0 0 0" />
      <geometry>
        <mesh
          filename="../meshes/r_f_link4_4.STL" />
      </geometry>
      <material
        name="">
        <color
          rgba="0.6 0.6 0.6 1" />
      </material>
    </visual>
    <collision>
      <origin
        xyz="0 0 0"
        rpy="0 0 0" />
      <geometry>
        <mesh
          filename="../meshes/r_f_link4_4.STL" />
      </geometry>
    </collision>
  </link>
  <joint
    name="r_f_joint4_4"
    type="revolute">
    <origin
      xyz="0.025 0 0"
      rpy="0 0 0" />
    <parent
      link="r_f_link4_3" />
    <child
      link="r_f_link4_4" />
    <axis
      xyz="0 0 1" />
    <limit lower="0" upper="1.3" effort="10" velocity="1.5" />
    <joint_properties damping="0.3" friction="0.5" />
  </joint>
  <link
    name="r_f_link5_1">
    <inertial>
      <origin xyz="0.0080017 1.8833E-05 -0.0015869" rpy="0 0 0" />
      <mass value="0.003769" />
      <inertia ixx="2.4739E-07" ixy="-9.1973E-10" ixz="5.2271E-08" iyy="3.9884E-07" iyz="-1.804E-10"
        izz="3.195E-07" />
    </inertial>
    <visual>
      <origin
        xyz="0 0 0"
        rpy="0 0 0" />
      <geometry>
        <mesh
          filename="../meshes/r_f_link5_1.STL" />
      </geometry>
      <material
        name="">
        <color
          rgba="0.792156862745098 0.819607843137255 0.933333333333333 1" />
      </material>
    </visual>
    <collision>
      <origin
        xyz="0 0 0"
        rpy="0 0 0" />
      <geometry>
        <mesh
          filename="../meshes/r_f_link5_1.STL" />
      </geometry>
    </collision>
  </link>
  <joint
    name="r_f_joint5_1"
    type="revolute">
    <origin
      xyz="0.006966 -0.037988 0.1504"
      rpy="3.1416 -1.5708 0" />
    <parent
      link="right_hand_base" />
    <child
      link="r_f_link5_1" />
    <axis
      xyz="0 0 1" />
    <limit lower="0" upper="0.6" effort="10" velocity="1.5" />
    <joint_properties damping="0.3" friction="0.5" />
  </joint>
  <link
    name="r_f_link5_2">
    <inertial>
      <origin
        xyz="0.02116 -0.00059146 -2.1978E-06"
        rpy="0 0 0" />
      <mass
        value="0.011802" />
      <inertia
        ixx="6.9559E-07"
        ixy="3.0616E-08"
        ixz="-1.7958E-09"
        iyy="2.0766E-06"
        iyz="-1.0846E-10"
        izz="2.0592E-06" />
    </inertial>
    <visual>
      <origin
        xyz="0 0 0"
        rpy="0 0 0" />
      <geometry>
        <mesh
          filename="../meshes/r_f_link5_2.STL" />
      </geometry>
      <material
        name="">
        <color
          rgba="0.6 0.6 0.6 1" />
      </material>
    </visual>
    <collision>
      <origin
        xyz="0 0 0"
        rpy="0 0 0" />
      <geometry>
        <mesh
          filename="../meshes/r_f_link5_2.STL" />
      </geometry>
    </collision>
  </link>
  <joint
    name="r_f_joint5_2"
    type="revolute">
    <origin
      xyz="0.017 0 0"
      rpy="1.5708 0 0" />
    <parent
      link="r_f_link5_1" />
    <child
      link="r_f_link5_2" />
    <axis
      xyz="0 0 1" />
    <limit lower="0" upper="1.3" effort="10" velocity="1.5" />
    <joint_properties damping="0.3" friction="0.5" />
  </joint>
  <link
    name="r_f_link5_3">
    <inertial>
      <origin
        xyz="0.013455 -0.00070241 -3.5727E-07"
        rpy="0 0 0" />
      <mass
        value="0.005726" />
      <inertia
        ixx="2.5543E-07"
        ixy="1.1107E-08"
        ixz="-1.7693E-11"
        iyy="4.4684E-07"
        iyz="-3.9296E-13"
        izz="4.7655E-07" />
    </inertial>
    <visual>
      <origin
        xyz="0 0 0"
        rpy="0 0 0" />
      <geometry>
        <mesh
          filename="../meshes/r_f_link5_3.STL" />
      </geometry>
      <material
        name="">
        <color
          rgba="0.6 0.6 0.6 1" />
      </material>
    </visual>
    <collision>
      <origin
        xyz="0 0 0"
        rpy="0 0 0" />
      <geometry>
        <mesh
          filename="../meshes/r_f_link5_3.STL" />
      </geometry>
    </collision>
  </link>
  <joint
    name="r_f_joint5_3"
    type="revolute">
    <origin
      xyz="0.043 0 0"
      rpy="0 0 0" />
    <parent
      link="r_f_link5_2" />
    <child
      link="r_f_link5_3" />
    <axis
      xyz="0 0 1" />
    <limit lower="0" upper="1.3" effort="10" velocity="1.5" />
    <joint_properties damping="0.3" friction="0.5" />
  </joint>
  <link
    name="r_f_link5_4">
    <inertial>
      <origin
        xyz="-0.11963 -0.015786 0.040234"
        rpy="0 0 0" />
      <mass
        value="0.0051136" />
      <inertia
        ixx="0.00061681"
        ixy="-0.00013518"
        ixz="-9.4865E-06"
        iyy="0.0021495"
        iyz="-6.4212E-05"
        izz="0.0017781" />
    </inertial>
    <visual>
      <origin
        xyz="0 0 0"
        rpy="0 0 0" />
      <geometry>
        <mesh
          filename="../meshes/r_f_link5_4.STL" />
      </geometry>
      <material
        name="">
        <color
          rgba="0.6 0.6 0.6 1" />
      </material>
    </visual>
    <collision>
      <origin
        xyz="0 0 0"
        rpy="0 0 0" />
      <geometry>
        <mesh
          filename="../meshes/r_f_link5_4.STL" />
      </geometry>
    </collision>
  </link>
  <joint
    name="r_f_joint5_4"
    type="revolute">
    <origin
      xyz="0.025 0 0"
      rpy="0 0 0" />
    <parent
      link="r_f_link5_3" />
    <child
      link="r_f_link5_4" />
    <axis
      xyz="0 0 1" />
    <limit lower="0" upper="1.3" effort="10" velocity="1.5" />
    <joint_properties damping="0.3" friction="0.5" />
  </joint>
  <!-- Right Hand Fingertips -->
  <link name="r_f_link1_tip">
    <inertial>
      <origin xyz="0 0 0.005" rpy="0 0 0" />
      <mass value="0.001" />
      <inertia ixx="1.0E-09" ixy="0.0" ixz="0.0" iyy="1.0E-09" iyz="0.0" izz="1.0E-09" />
    </inertial>
    <visual>
      <origin xyz="0.015 -0.004 0" rpy="0 0 0" />
      <geometry>
        <sphere radius="0.002" />
      </geometry>
      <material name="">
        <color rgba="1 0 0 1" />
      </material>
    </visual>
    <collision>
      <origin xyz="0 0 0" rpy="0 0 0" />
      <geometry>
        <sphere radius="0.002" />
      </geometry>
    </collision>
  </link>

  <joint name="r_f_joint1_tip" type="fixed">
    <origin xyz="0.02 0 0" rpy="0 0 0" />
    <parent link="r_f_link1_4" />
    <child link="r_f_link1_tip" />
  </joint>

  <link name="r_f_link2_tip">
    <inertial>
      <origin xyz="0 0 0.005" rpy="0 0 0" />
      <mass value="0.001" />
      <inertia ixx="1.0E-09" ixy="0.0" ixz="0.0" iyy="1.0E-09" iyz="0.0" izz="1.0E-09" />
    </inertial>
    <visual>
      <origin xyz="0.015 -0.004 0" rpy="0 0 0" />
      <geometry>
        <sphere radius="0.002" />
      </geometry>
      <material name="">
        <color rgba="1 0 0 1" />
      </material>
    </visual>
    <collision>
      <origin xyz="0 0 0" rpy="0 0 0" />
      <geometry>
        <sphere radius="0.002" />
      </geometry>
    </collision>
  </link>

  <joint name="r_f_joint2_tip" type="fixed">
    <origin xyz="0.02 0 0" rpy="0 0 0" />
    <parent link="r_f_link2_4" />
    <child link="r_f_link2_tip" />
  </joint>

  <link name="r_f_link3_tip">
    <inertial>
      <origin xyz="0 0 0.005" rpy="0 0 0" />
      <mass value="0.001" />
      <inertia ixx="1.0E-09" ixy="0.0" ixz="0.0" iyy="1.0E-09" iyz="0.0" izz="1.0E-09" />
    </inertial>
    <visual>
      <origin xyz="0.015 -0.004 0" rpy="0 0 0" />
      <geometry>
        <sphere radius="0.002" />
      </geometry>
      <material name="">
        <color rgba="1 0 0 1" />
      </material>
    </visual>
    <collision>
      <origin xyz="0 0 0" rpy="0 0 0" />
      <geometry>
        <sphere radius="0.002" />
      </geometry>
    </collision>
  </link>

  <joint name="r_f_joint3_tip" type="fixed">
    <origin xyz="0.02 0 0" rpy="0 0 0" />
    <parent link="r_f_link3_4" />
    <child link="r_f_link3_tip" />
  </joint>

  <link name="r_f_link4_tip">
    <inertial>
      <origin xyz="0 0 0.005" rpy="0 0 0" />
      <mass value="0.001" />
      <inertia ixx="1.0E-09" ixy="0.0" ixz="0.0" iyy="1.0E-09" iyz="0.0" izz="1.0E-09" />
    </inertial>
    <visual>
      <origin xyz="0.015 -0.004 0" rpy="0 0 0" />
      <geometry>
        <sphere radius="0.002" />
      </geometry>
      <material name="">
        <color rgba="1 0 0 1" />
      </material>
    </visual>
    <collision>
      <origin xyz="0 0 0" rpy="0 0 0" />
      <geometry>
        <sphere radius="0.002" />
      </geometry>
    </collision>
  </link>

  <joint name="r_f_joint4_tip" type="fixed">
    <origin xyz="0.02 0 0" rpy="0 0 0" />
    <parent link="r_f_link4_4" />
    <child link="r_f_link4_tip" />
  </joint>

  <link name="r_f_link5_tip">
    <inertial>
      <origin xyz="0 0 0.005" rpy="0 0 0" />
      <mass value="0.001" />
      <inertia ixx="1.0E-09" ixy="0.0" ixz="0.0" iyy="1.0E-09" iyz="0.0" izz="1.0E-09" />
    </inertial>
    <visual>
      <origin xyz="0.015 -0.004 0" rpy="0 0 0" />
      <geometry>
        <sphere radius="0.002" />
      </geometry>
      <material name="">
        <color rgba="1 0 0 1" />
      </material>
    </visual>
    <collision>
      <origin xyz="0 0 0" rpy="0 0 0" />
      <geometry>
        <sphere radius="0.002" />
      </geometry>
    </collision>
  </link>

  <joint name="r_f_joint5_tip" type="fixed">
    <origin xyz="0.02 0 0" rpy="0 0 0" />
    <parent link="r_f_link5_4" />
    <child link="r_f_link5_tip" />
  </joint>
</robot>
