<?xml version="1.0" encoding="utf-8"?>

<robot
  name="dexhand021_left_simplified">

  <mujoco>
    <compiler meshdir="../meshes/dexhand021_simplified" balanceinertia="true" discardvisual="false" />
  </mujoco>

  <link
    name="left_hand_base">
    <inertial>
      <origin
        xyz="-0.015115 4.3384E-05 0.09592"
        rpy="0 0 0" />
      <mass value="0.37509" />
      <inertia ixx="0.0004174" ixy="3.0809E-06" ixz="2.7137E-05" iyy="0.00056243" iyz="4.0143E-05"
        izz="0.00021494" />
    </inertial>
    <visual>
      <origin
        xyz="0 0 0"
        rpy="0 0 0" />
      <geometry>
        <mesh
          filename="../meshes/left_hand_base.STL" />
      </geometry>
      <material
        name="">
        <color
          rgba="0.75294 0.75294 0.75294 1" />
      </material>
    </visual>
    <collision>
      <origin
        xyz="0 0 0"
        rpy="0 0 0" />
      <geometry>
        <mesh
          filename="../meshes/left_hand_base.STL" />
      </geometry>
    </collision>
  </link>
  <link
    name="l_f_link1_1">
    <inertial>
      <origin
        xyz="0.00198600910498237 -0.000349747755566558 -0.0134844142067587"
        rpy="0 0 0" />
      <mass
        value="0.0055493" />
      <inertia
        ixx="4.7024288531666E-07"
        ixy="4.454983699583E-09"
        ixz="-4.16334875297436E-08"
        iyy="5.5177651806112E-07"
        iyz="1.08245533973591E-08"
        izz="2.56258780482512E-07" />
    </inertial>
    <visual>
      <origin
        xyz="0 0 0"
        rpy="0 0 0" />
      <geometry>
        <mesh
          filename="../meshes/l_f_link1_1.STL" />
      </geometry>
      <material
        name="">
        <color
          rgba="0.6 0.6 0.6 1" />
      </material>
    </visual>
    <collision>
      <origin
        xyz="0 0 0"
        rpy="0 0 0" />
      <geometry>
        <mesh
          filename="../meshes/l_f_link1_1.STL" />
      </geometry>
    </collision>
  </link>
  <joint
    name="l_f_joint1_1"
    type="revolute">
    <origin
      xyz="0.032783 -0.023781 0.11211"
      rpy="-0.26842 -0.15197 -1.3168" />
    <parent
      link="left_hand_base" />
    <child
      link="l_f_link1_1" />
    <axis
      xyz="0 0 1" />
    <limit lower="0" upper="2.2" effort="10" velocity="1.5" />
    <joint_properties damping="0.3" friction="0.5" />
  </joint>
  <link
    name="l_f_link1_2">
    <inertial>
      <origin
        xyz="0.0214366856889457 0.000173154923003682 0.001298307943995"
        rpy="0 0 0" />
      <mass
        value="0.0124624337931872" />
      <inertia
        ixx="7.78577931986097E-07"
        ixy="5.44832818046826E-08"
        ixz="1.5891863798302E-09"
        iyy="2.07494140526537E-06"
        iyz="3.38295093879597E-10"
        izz="2.14499509195747E-06" />
    </inertial>
    <visual>
      <origin
        xyz="0 0 0"
        rpy="0 0 0" />
      <geometry>
        <mesh
          filename="../meshes/l_f_link1_2.STL" />
      </geometry>
      <material
        name="">
        <color
          rgba="0.6 0.6 0.6 1" />
      </material>
    </visual>
    <collision>
      <origin
        xyz="0 0 0"
        rpy="0 0 0" />
      <geometry>
        <mesh
          filename="../meshes/l_f_link1_2.STL" />
      </geometry>
    </collision>
  </link>
  <joint
    name="l_f_joint1_2"
    type="revolute">
    <origin
      xyz="0.0083307 0 0"
      rpy="1.5708 0 0" />
    <parent
      link="l_f_link1_1" />
    <child
      link="l_f_link1_2" />
    <axis
      xyz="0 0 1" />
    <limit lower="0" upper="1.3" effort="10" velocity="1.5" />
    <joint_properties damping="0.3" friction="0.6" />
  </joint>
  <link
    name="l_f_link1_3">
    <inertial>
      <origin
        xyz="0.0134548296294729 -0.000702414639214777 0.00129279825600215"
        rpy="0 0 0" />
      <mass
        value="0.00572598940663931" />
      <inertia
        ixx="2.55427275443236E-07"
        ixy="1.11119279570581E-08"
        ixz="2.31215404124848E-11"
        iyy="4.46844563002543E-07"
        iyz="-8.01009905021208E-12"
        izz="4.76544917652253E-07" />
    </inertial>
    <visual>
      <origin
        xyz="0 0 0"
        rpy="0 0 0" />
      <geometry>
        <mesh
          filename="../meshes/l_f_link1_3.STL" />
      </geometry>
      <material
        name="">
        <color
          rgba="0.6 0.6 0.6 1" />
      </material>
    </visual>
    <collision>
      <origin
        xyz="0 0 0"
        rpy="0 0 0" />
      <geometry>
        <mesh
          filename="../meshes/l_f_link1_3.STL" />
      </geometry>
    </collision>
  </link>
  <joint
    name="l_f_joint1_3"
    type="revolute">
    <origin
      xyz="0.043 0 0"
      rpy="0 0 0" />
    <parent
      link="l_f_link1_2" />
    <child
      link="l_f_link1_3" />
    <axis
      xyz="0 0 1" />
    <limit lower="0" upper="1.3" effort="10" velocity="1.5" />
    <joint_properties damping="0.3" friction="0.6" />
  </joint>
  <link
    name="l_f_link1_4">
    <inertial>
      <origin
        xyz="-0.106710222868991 -0.00118159216051819 0.0358277359301637"
        rpy="0 0 0" />
      <mass
        value="0.00511359728172243" />
      <inertia
        ixx="0.00173095008951806"
        ixy="-0.000202313478926414"
        ixz="-7.05472104546055E-05"
        iyy="0.000694149825004719"
        iyz="-0.000270292828807616"
        izz="0.00211927243947017" />
    </inertial>
    <visual>
      <origin
        xyz="0 0 0"
        rpy="0 0 0" />
      <geometry>
        <mesh
          filename="../meshes/l_f_link1_4.STL" />
      </geometry>
      <material
        name="">
        <color
          rgba="0.6 0.6 0.6 1" />
      </material>
    </visual>
    <collision>
      <origin
        xyz="0 0 0"
        rpy="0 0 0" />
      <geometry>
        <mesh
          filename="../meshes/l_f_link1_4.STL" />
      </geometry>
    </collision>
  </link>
  <joint
    name="l_f_joint1_4"
    type="revolute">
    <origin
      xyz="0.025 0 0"
      rpy="0 0 0" />
    <parent
      link="l_f_link1_3" />
    <child
      link="l_f_link1_4" />
    <axis
      xyz="0 0 1" />
    <limit lower="0" upper="1.3" effort="10" velocity="1.5" />
    <joint_properties damping="0.3" friction="0.6" />
  </joint>
  <link
    name="l_f_link2_1">
    <inertial>
      <origin
        xyz="0.00700303228678785 1.36491595803534E-10 -0.000969320716374398"
        rpy="0 0 0" />
      <mass
        value="0.00512730147699983" />
      <inertia
        ixx="2.7295663921666E-07"
        ixy="-1.22250330409963E-13"
        ixz="3.39749457195655E-08"
        iyy="3.98794075399136E-07"
        iyz="-7.13636872604662E-13"
        izz="3.23508501141432E-07" />
    </inertial>
    <visual>
      <origin
        xyz="0 0 0"
        rpy="0 0 0" />
      <geometry>
        <mesh
          filename="../meshes/l_f_link2_1.STL" />
      </geometry>
      <material
        name="">
        <color
          rgba="0.792156862745098 0.819607843137255 0.933333333333333 1" />
      </material>
    </visual>
    <collision>
      <origin
        xyz="0 0 0"
        rpy="0 0 0" />
      <geometry>
        <mesh
          filename="../meshes/l_f_link2_1.STL" />
      </geometry>
    </collision>
  </link>
  <joint
    name="l_f_joint2_1"
    type="revolute">
    <origin
      xyz="0.006966 -0.034912 0.1644"
      rpy="3.1416 -1.5708 0" />
    <parent
      link="left_hand_base" />
    <child
      link="l_f_link2_1" />
    <axis
      xyz="0 0 1" />
    <limit lower="0" upper="0.6" effort="10" velocity="1.5" />
    <joint_properties damping="0.3" friction="0.6" />
  </joint>
  <link
    name="l_f_link2_2">
    <inertial>
      <origin
        xyz="0.0211604709123078 -0.000591445999095427 2.29149645292193E-06"
        rpy="0 0 0" />
      <mass
        value="0.011802504617909" />
      <inertia
        ixx="6.95572718028951E-07"
        ixy="3.06110038221272E-08"
        ixz="1.7898851370774E-09"
        iyy="2.07663070640492E-06"
        iyz="1.12335230360223E-10"
        izz="2.05914603414923E-06" />
    </inertial>
    <visual>
      <origin
        xyz="0 0 0"
        rpy="0 0 0" />
      <geometry>
        <mesh
          filename="../meshes/l_f_link2_2.STL" />
      </geometry>
      <material
        name="">
        <color
          rgba="0.6 0.6 0.6 1" />
      </material>
    </visual>
    <collision>
      <origin
        xyz="0 0 0"
        rpy="0 0 0" />
      <geometry>
        <mesh
          filename="../meshes/l_f_link2_2.STL" />
      </geometry>
    </collision>
  </link>
  <joint
    name="l_f_joint2_2"
    type="revolute">
    <origin
      xyz="0.017 0 0"
      rpy="1.5708 0 0" />
    <parent
      link="l_f_link2_1" />
    <child
      link="l_f_link2_2" />
    <axis
      xyz="0 0 1" />
    <limit lower="0" upper="1.3" effort="10" velocity="1.5" />
    <joint_properties damping="0.3" friction="0.6" />
  </joint>
  <link
    name="l_f_link2_3">
    <inertial>
      <origin
        xyz="0.0134548153053672 -0.000702381707239779 3.81155380702047E-07"
        rpy="0 0 0" />
      <mass
        value="0.0057259887397435" />
      <inertia
        ixx="2.55428310123141E-07"
        ixy="1.1111381574676E-08"
        ixz="2.25321389711504E-11"
        iyy="4.46843623646942E-07"
        iyz="-6.58573110647318E-12"
        izz="4.7654539911187E-07" />
    </inertial>
    <visual>
      <origin
        xyz="0 0 0"
        rpy="0 0 0" />
      <geometry>
        <mesh
          filename="../meshes/l_f_link2_3.STL" />
      </geometry>
      <material
        name="">
        <color
          rgba="0.6 0.6 0.6 1" />
      </material>
    </visual>
    <collision>
      <origin
        xyz="0 0 0"
        rpy="0 0 0" />
      <geometry>
        <mesh
          filename="../meshes/l_f_link2_3.STL" />
      </geometry>
    </collision>
  </link>
  <joint
    name="l_f_joint2_3"
    type="revolute">
    <origin
      xyz="0.043 0 0"
      rpy="0 0 0" />
    <parent
      link="l_f_link2_2" />
    <child
      link="l_f_link2_3" />
    <axis
      xyz="0 0 1" />
    <limit lower="0" upper="1.3" effort="10" velocity="1.5" />
    <joint_properties damping="0.3" friction="0.6" />
  </joint>
  <link
    name="l_f_link2_4">
    <inertial>
      <origin
        xyz="-0.13362728668981 -0.0157854249828589 0.0326660778157223"
        rpy="0 0 0" />
      <mass
        value="0.00511359728172243" />
      <inertia
        ixx="0.00061680506465688"
        ixy="-0.000135176421458247"
        ixz="9.49130763997119E-06"
        iyy="0.00214948104653407"
        iyz="6.42111861959019E-05"
        izz="0.001778086242802" />
    </inertial>
    <visual>
      <origin
        xyz="0 0 0"
        rpy="0 0 0" />
      <geometry>
        <mesh
          filename="../meshes/l_f_link2_4.STL" />
      </geometry>
      <material
        name="">
        <color
          rgba="0.6 0.6 0.6 1" />
      </material>
    </visual>
    <collision>
      <origin
        xyz="0 0 0"
        rpy="0 0 0" />
      <geometry>
        <mesh
          filename="../meshes/l_f_link2_4.STL" />
      </geometry>
    </collision>
  </link>
  <joint
    name="l_f_joint2_4"
    type="revolute">
    <origin
      xyz="0.025 0 0"
      rpy="0 0 0" />
    <parent
      link="l_f_link2_3" />
    <child
      link="l_f_link2_4" />
    <axis
      xyz="0 0 1" />
    <limit lower="0" upper="1.3" effort="10" velocity="1.5" />
    <joint_properties damping="0.3" friction="0.6" />
  </joint>
  <link
    name="l_f_link3_1">
    <inertial>
      <origin
        xyz="0.00700303602704492 1.36491595803534E-10 -0.000969317075562619"
        rpy="0 0 0" />
      <mass
        value="0.00512729840681515" />
      <inertia
        ixx="2.72956517525723E-07"
        ixy="-1.22250325596393E-13"
        ixz="3.39750623257501E-08"
        iyy="3.98793842096755E-07"
        iyz="-7.13636871485365E-13"
        izz="3.23508373161817E-07" />
    </inertial>
    <visual>
      <origin
        xyz="0 0 0"
        rpy="0 0 0" />
      <geometry>
        <mesh
          filename="../meshes/l_f_link3_1.STL" />
      </geometry>
      <material
        name="">
        <color
          rgba="0.792156862745098 0.819607843137255 0.933333333333333 1" />
      </material>
    </visual>
    <collision>
      <origin
        xyz="0 0 0"
        rpy="0 0 0" />
      <geometry>
        <mesh
          filename="../meshes/l_f_link3_1.STL" />
      </geometry>
    </collision>
  </link>
  <joint
    name="l_f_joint3_1"
    type="revolute">
    <origin
      xyz="0.006966 -0.010612 0.1734"
      rpy="3.1416 -1.5708 0" />
    <parent
      link="left_hand_base" />
    <child
      link="l_f_link3_1" />
    <axis
      xyz="0 0 1" />
    <limit lower="-0.001" upper="0.001" effort="10" velocity="1.5" />
    <joint_properties damping="0.3" friction="0.6" />
  </joint>
  <link
    name="l_f_link3_2">
    <inertial>
      <origin
        xyz="0.0211604709123072 -0.000591445999095455 2.29149645325499E-06"
        rpy="0 0 0" />
      <mass
        value="0.011802504617909" />
      <inertia
        ixx="6.95572718028953E-07"
        ixy="3.06110038221223E-08"
        ixz="1.78988513706649E-09"
        iyy="2.07663070640493E-06"
        iyz="1.12335230358326E-10"
        izz="2.05914603414924E-06" />
    </inertial>
    <visual>
      <origin
        xyz="0 0 0"
        rpy="0 0 0" />
      <geometry>
        <mesh
          filename="../meshes/l_f_link3_2.STL" />
      </geometry>
      <material
        name="">
        <color
          rgba="0.6 0.6 0.6 1" />
      </material>
    </visual>
    <collision>
      <origin
        xyz="0 0 0"
        rpy="0 0 0" />
      <geometry>
        <mesh
          filename="../meshes/l_f_link3_2.STL" />
      </geometry>
    </collision>
  </link>
  <joint
    name="l_f_joint3_2"
    type="revolute">
    <origin
      xyz="0.017 0 0"
      rpy="1.5708 0 0" />
    <parent
      link="l_f_link3_1" />
    <child
      link="l_f_link3_2" />
    <axis
      xyz="0 0 1" />
    <limit lower="0" upper="1.3" effort="10" velocity="1.5" />
    <joint_properties damping="0.3" friction="0.6" />
  </joint>
  <link
    name="l_f_link3_3">
    <inertial>
      <origin
        xyz="0.0134548153053674 -0.000702381707239831 3.8115538081307E-07"
        rpy="0 0 0" />
      <mass
        value="0.00572598873974363" />
      <inertia
        ixx="2.55428310123148E-07"
        ixy="1.11113815746774E-08"
        ixz="2.25321389705957E-11"
        iyy="4.46843623646947E-07"
        iyz="-6.58573110714898E-12"
        izz="4.76545399111875E-07" />
    </inertial>
    <visual>
      <origin
        xyz="0 0 0"
        rpy="0 0 0" />
      <geometry>
        <mesh
          filename="../meshes/l_f_link3_3.STL" />
      </geometry>
      <material
        name="">
        <color
          rgba="0.6 0.6 0.6 1" />
      </material>
    </visual>
    <collision>
      <origin
        xyz="0 0 0"
        rpy="0 0 0" />
      <geometry>
        <mesh
          filename="../meshes/l_f_link3_3.STL" />
      </geometry>
    </collision>
  </link>
  <joint
    name="l_f_joint3_3"
    type="revolute">
    <origin
      xyz="0.043 0 0"
      rpy="0 0 0" />
    <parent
      link="l_f_link3_2" />
    <child
      link="l_f_link3_3" />
    <axis
      xyz="0 0 1" />
    <limit lower="0" upper="1.3" effort="10" velocity="1.5" />
    <joint_properties damping="0.3" friction="0.6" />
  </joint>
  <link
    name="l_f_link3_4">
    <inertial>
      <origin
        xyz="-0.1426272866905 -0.0157854249835522 0.00836607781572185"
        rpy="0 0 0" />
      <mass
        value="0.00511359728172243" />
      <inertia
        ixx="0.000616805064659985"
        ixy="-0.000135176421475851"
        ixz="9.49130763923698E-06"
        iyy="0.00214948104653096"
        iyz="6.42111861960076E-05"
        izz="0.001778086242802" />
    </inertial>
    <visual>
      <origin
        xyz="0 0 0"
        rpy="0 0 0" />
      <geometry>
        <mesh
          filename="../meshes/l_f_link3_4.STL" />
      </geometry>
      <material
        name="">
        <color
          rgba="0.6 0.6 0.6 1" />
      </material>
    </visual>
    <collision>
      <origin
        xyz="0 0 0"
        rpy="0 0 0" />
      <geometry>
        <mesh
          filename="../meshes/l_f_link3_4.STL" />
      </geometry>
    </collision>
  </link>
  <joint
    name="l_f_joint3_4"
    type="revolute">
    <origin
      xyz="0.025 0 0"
      rpy="0 0 0" />
    <parent
      link="l_f_link3_3" />
    <child
      link="l_f_link3_4" />
    <axis
      xyz="0 0 1" />
    <limit lower="0" upper="1.3" effort="10" velocity="1.5" />
    <joint_properties damping="0.3" friction="0.6" />
  </joint>
  <link
    name="l_f_link4_1">
    <inertial>
      <origin
        xyz="0.00700303490017868 -1.36491706825836E-10 0.000969318172471371"
        rpy="0 0 0" />
      <mass
        value="0.00512729933180569" />
      <inertia
        ixx="2.7295655407302E-07"
        ixy="1.22250327077853E-13"
        ixz="-3.39750271946444E-08"
        iyy="3.98793912386068E-07"
        iyz="-7.13636871093389E-13"
        izz="3.23508411603554E-07" />
    </inertial>
    <visual>
      <origin
        xyz="0 0 0"
        rpy="0 0 0" />
      <geometry>
        <mesh
          filename="../meshes/l_f_link4_1.STL" />
      </geometry>
      <material
        name="">
        <color
          rgba="0.792156862745098 0.819607843137255 0.933333333333333 1" />
      </material>
    </visual>
    <collision>
      <origin
        xyz="0 0 0"
        rpy="0 0 0" />
      <geometry>
        <mesh
          filename="../meshes/l_f_link4_1.STL" />
      </geometry>
    </collision>
  </link>
  <joint
    name="l_f_joint4_1"
    type="revolute">
    <origin
      xyz="0.006966 0.013688 0.1644"
      rpy="0 -1.5708 0" />
    <parent
      link="left_hand_base" />
    <child
      link="l_f_link4_1" />
    <axis
      xyz="0 0 1" />
    <limit lower="0" upper="0.6" effort="10" velocity="1.5" />
    <joint_properties damping="0.3" friction="0.6" />
  </joint>
  <link
    name="l_f_link4_2">
    <inertial>
      <origin
        xyz="0.0211604718221049 -0.000591444849743565 2.29173686316919E-06"
        rpy="0 0 0" />
      <mass
        value="0.0118025067643813" />
      <inertia
        ixx="6.95572810469925E-07"
        ixy="3.06109309134445E-08"
        ixz="1.78986618807753E-09"
        iyy="2.07663075277299E-06"
        iyz="1.12316142746841E-10"
        izz="2.05914617403501E-06" />
    </inertial>
    <visual>
      <origin
        xyz="0 0 0"
        rpy="0 0 0" />
      <geometry>
        <mesh
          filename="../meshes/l_f_link4_2.STL" />
      </geometry>
      <material
        name="">
        <color
          rgba="0.6 0.6 0.6 1" />
      </material>
    </visual>
    <collision>
      <origin
        xyz="0 0 0"
        rpy="0 0 0" />
      <geometry>
        <mesh
          filename="../meshes/l_f_link4_2.STL" />
      </geometry>
    </collision>
  </link>
  <joint
    name="l_f_joint4_2"
    type="revolute">
    <origin
      xyz="0.017 0 0"
      rpy="-1.5708 0 0" />
    <parent
      link="l_f_link4_1" />
    <child
      link="l_f_link4_2" />
    <axis
      xyz="0 0 1" />
    <limit lower="0" upper="1.3" effort="10" velocity="1.5" />
    <joint_properties damping="0.3" friction="0.6" />
  </joint>
  <link
    name="l_f_link4_3">
    <inertial>
      <origin
        xyz="0.0134548153053673 -0.000702381707239822 3.81155380591025E-07"
        rpy="0 0 0" />
      <mass
        value="0.00572598873974366" />
      <inertia
        ixx="2.55428310123149E-07"
        ixy="1.11113815746773E-08"
        ixz="2.25321389715399E-11"
        iyy="4.46843623646948E-07"
        iyz="-6.58573110698767E-12"
        izz="4.76545399111878E-07" />
    </inertial>
    <visual>
      <origin
        xyz="0 0 0"
        rpy="0 0 0" />
      <geometry>
        <mesh
          filename="../meshes/l_f_link4_3.STL" />
      </geometry>
      <material
        name="">
        <color
          rgba="0.6 0.6 0.6 1" />
      </material>
    </visual>
    <collision>
      <origin
        xyz="0 0 0"
        rpy="0 0 0" />
      <geometry>
        <mesh
          filename="../meshes/l_f_link4_3.STL" />
      </geometry>
    </collision>
  </link>
  <joint
    name="l_f_joint4_3"
    type="revolute">
    <origin
      xyz="0.043 0 0"
      rpy="0 0 0" />
    <parent
      link="l_f_link4_2" />
    <child
      link="l_f_link4_3" />
    <axis
      xyz="0 0 1" />
    <limit lower="0" upper="1.3" effort="10" velocity="1.5" />
    <joint_properties damping="0.3" friction="0.6" />
  </joint>
  <link
    name="l_f_link4_4">
    <inertial>
      <origin
        xyz="-0.13362728668973 -0.0157854249827552 -0.0159339221842777"
        rpy="0 0 0" />
      <mass
        value="0.00511359728172243" />
      <inertia
        ixx="0.00061680506465688"
        ixy="-0.000135176421458247"
        ixz="9.49130763997118E-06"
        iyy="0.00214948104653407"
        iyz="6.42111861959019E-05"
        izz="0.001778086242802" />
    </inertial>
    <visual>
      <origin
        xyz="0 0 0"
        rpy="0 0 0" />
      <geometry>
        <mesh
          filename="../meshes/l_f_link4_4.STL" />
      </geometry>
      <material
        name="">
        <color
          rgba="0.6 0.6 0.6 1" />
      </material>
    </visual>
    <collision>
      <origin
        xyz="0 0 0"
        rpy="0 0 0" />
      <geometry>
        <mesh
          filename="../meshes/l_f_link4_4.STL" />
      </geometry>
    </collision>
  </link>
  <joint
    name="l_f_joint4_4"
    type="revolute">
    <origin
      xyz="0.025 0 0"
      rpy="0 0 0" />
    <parent
      link="l_f_link4_3" />
    <child
      link="l_f_link4_4" />
    <axis
      xyz="0 0 1" />
    <limit lower="0" upper="1.3" effort="10" velocity="1.5" />
    <joint_properties damping="0.3" friction="0.6" />
  </joint>
  <link
    name="l_f_link5_1">
    <inertial>
      <origin
        xyz="0.00700303415129234 -1.36491706825836E-10 0.000969318901447381"
        rpy="0 0 0" />
      <mass
        value="0.00512729994652864" />
      <inertia
        ixx="2.7295657841603E-07"
        ixy="1.2225032591792E-13"
        ixz="-3.3975003847395E-08"
        iyy="3.98793959098605E-07"
        iyz="-7.13636872825627E-13"
        izz="3.23508437205666E-07" />
    </inertial>
    <visual>
      <origin
        xyz="0 0 0"
        rpy="0 0 0" />
      <geometry>
        <mesh
          filename="../meshes/l_f_link5_1.STL" />
      </geometry>
      <material
        name="">
        <color
          rgba="0.792156862745098 0.819607843137255 0.933333333333333 1" />
      </material>
    </visual>
    <collision>
      <origin
        xyz="0 0 0"
        rpy="0 0 0" />
      <geometry>
        <mesh
          filename="../meshes/l_f_link5_1.STL" />
      </geometry>
    </collision>
  </link>
  <joint
    name="l_f_joint5_1"
    type="revolute">
    <origin
      xyz="0.006966 0.037988 0.1504"
      rpy="0 -1.5708 0" />
    <parent
      link="left_hand_base" />
    <child
      link="l_f_link5_1" />
    <axis
      xyz="0 0 1" />
    <limit lower="0" upper="0.6" effort="10" velocity="1.5" />
    <joint_properties damping="0.3" friction="0.6" />
  </joint>
  <link
    name="l_f_link5_2">
    <inertial>
      <origin
        xyz="0.0211604718221046 -0.000591444849743758 2.2917368632247E-06"
        rpy="0 0 0" />
      <mass
        value="0.0118025067643815" />
      <inertia
        ixx="6.95572810469934E-07"
        ixy="3.0610930913427E-08"
        ixz="1.78986618807448E-09"
        iyy="2.076630752773E-06"
        iyz="1.12316142751315E-10"
        izz="2.05914617403502E-06" />
    </inertial>
    <visual>
      <origin
        xyz="0 0 0"
        rpy="0 0 0" />
      <geometry>
        <mesh
          filename="../meshes/l_f_link5_2.STL" />
      </geometry>
      <material
        name="">
        <color
          rgba="0.6 0.6 0.6 1" />
      </material>
    </visual>
    <collision>
      <origin
        xyz="0 0 0"
        rpy="0 0 0" />
      <geometry>
        <mesh
          filename="../meshes/l_f_link5_2.STL" />
      </geometry>
    </collision>
  </link>
  <joint
    name="l_f_joint5_2"
    type="revolute">
    <origin
      xyz="0.017 0 0"
      rpy="-1.5708 0 0" />
    <parent
      link="l_f_link5_1" />
    <child
      link="l_f_link5_2" />
    <axis
      xyz="0 0 1" />
    <limit lower="0" upper="1.3" effort="10" velocity="1.5" />
    <joint_properties damping="0.3" friction="0.6" />
  </joint>
  <link
    name="l_f_link5_3">
    <inertial>
      <origin
        xyz="0.0134548153053674 -0.000702381707239666 3.81155380702047E-07"
        rpy="0 0 0" />
      <mass
        value="0.00572598873974358" />
      <inertia
        ixx="2.55428310123145E-07"
        ixy="1.11113815746782E-08"
        ixz="2.2532138970385E-11"
        iyy="4.46843623646946E-07"
        iyz="-6.58573110690028E-12"
        izz="4.76545399111873E-07" />
    </inertial>
    <visual>
      <origin
        xyz="0 0 0"
        rpy="0 0 0" />
      <geometry>
        <mesh
          filename="../meshes/l_f_link5_3.STL" />
      </geometry>
      <material
        name="">
        <color
          rgba="0.6 0.6 0.6 1" />
      </material>
    </visual>
    <collision>
      <origin
        xyz="0 0 0"
        rpy="0 0 0" />
      <geometry>
        <mesh
          filename="../meshes/l_f_link5_3.STL" />
      </geometry>
    </collision>
  </link>
  <joint
    name="l_f_joint5_3"
    type="revolute">
    <origin
      xyz="0.043 0 0"
      rpy="0 0 0" />
    <parent
      link="l_f_link5_2" />
    <child
      link="l_f_link5_3" />
    <axis
      xyz="0 0 1" />
    <limit lower="0" upper="1.3" effort="10" velocity="1.5" />
    <joint_properties damping="0.3" friction="0.6" />
  </joint>
  <link
    name="l_f_link5_4">
    <inertial>
      <origin
        xyz="-0.119627286690287 -0.015785424982547 -0.0402339221842787"
        rpy="0 0 0" />
      <mass
        value="0.00511359728172243" />
      <inertia
        ixx="0.00061680506465688"
        ixy="-0.000135176421458248"
        ixz="9.49130763997079E-06"
        iyy="0.00214948104653407"
        iyz="6.42111861958955E-05"
        izz="0.001778086242802" />
    </inertial>
    <visual>
      <origin
        xyz="0 0 0"
        rpy="0 0 0" />
      <geometry>
        <mesh
          filename="../meshes/l_f_link5_4.STL" />
      </geometry>
      <material
        name="">
        <color
          rgba="0.6 0.6 0.6 1" />
      </material>
    </visual>
    <collision>
      <origin
        xyz="0 0 0"
        rpy="0 0 0" />
      <geometry>
        <mesh
          filename="../meshes/l_f_link5_4.STL" />
      </geometry>
    </collision>
  </link>
  <joint
    name="l_f_joint5_4"
    type="revolute">
    <origin
      xyz="0.025 0 0"
      rpy="0 0 0" />
    <parent
      link="l_f_link5_3" />
    <child
      link="l_f_link5_4" />
    <axis
      xyz="0 0 1" />
    <limit lower="0" upper="1.3" effort="10" velocity="1.5" />
    <joint_properties damping="0.3" friction="0.6" />
  </joint>

  <!-- Left Hand Fingertips -->
  <link name="l_f_link1_tip">
    <inertial>
      <origin xyz="0 0 0.005" rpy="0 0 0" />
      <mass value="0.001" />
      <inertia ixx="1.0E-09" ixy="0.0" ixz="0.0" iyy="1.0E-09" iyz="0.0" izz="1.0E-09" />
    </inertial>
    <visual>
      <origin xyz="0.015 -0.004 0" rpy="0 0 0" />
      <geometry>
        <sphere radius="0.002" />
      </geometry>
      <material name="">
        <color rgba="1 0 0 1" />
      </material>
    </visual>
    <collision>
      <origin xyz="0 0 0" rpy="0 0 0" />
      <geometry>
        <sphere radius="0.002" />
      </geometry>
    </collision>
  </link>

  <joint name="l_f_joint1_tip" type="fixed">
    <origin xyz="0.02 0 0" rpy="0 0 0" />
    <parent link="l_f_link1_4" />
    <child link="l_f_link1_tip" />
  </joint>

  <link name="l_f_link2_tip">
    <inertial>
      <origin xyz="0 0 0.005" rpy="0 0 0" />
      <mass value="0.001" />
      <inertia ixx="1.0E-09" ixy="0.0" ixz="0.0" iyy="1.0E-09" iyz="0.0" izz="1.0E-09" />
    </inertial>
    <visual>
      <origin xyz="0.015 -0.004 0" rpy="0 0 0" />
      <geometry>
        <sphere radius="0.002" />
      </geometry>
      <material name="">
        <color rgba="1 0 0 1" />
      </material>
    </visual>
    <collision>
      <origin xyz="0 0 0" rpy="0 0 0" />
      <geometry>
        <sphere radius="0.002" />
      </geometry>
    </collision>
  </link>

  <joint name="l_f_joint2_tip" type="fixed">
    <origin xyz="0.02 0 0" rpy="0 0 0" />
    <parent link="l_f_link2_4" />
    <child link="l_f_link2_tip" />
  </joint>

  <link name="l_f_link3_tip">
    <inertial>
      <origin xyz="0 0 0.005" rpy="0 0 0" />
      <mass value="0.001" />
      <inertia ixx="1.0E-09" ixy="0.0" ixz="0.0" iyy="1.0E-09" iyz="0.0" izz="1.0E-09" />
    </inertial>
    <visual>
      <origin xyz="0.015 -0.004 0" rpy="0 0 0" />
      <geometry>
        <sphere radius="0.002" />
      </geometry>
      <material name="">
        <color rgba="1 0 0 1" />
      </material>
    </visual>
    <collision>
      <origin xyz="0 0 0" rpy="0 0 0" />
      <geometry>
        <sphere radius="0.002" />
      </geometry>
    </collision>
  </link>

  <joint name="l_f_joint3_tip" type="fixed">
    <origin xyz="0.02 0 0" rpy="0 0 0" />
    <parent link="l_f_link3_4" />
    <child link="l_f_link3_tip" />
  </joint>

  <link name="l_f_link4_tip">
    <inertial>
      <origin xyz="0 0 0.005" rpy="0 0 0" />
      <mass value="0.001" />
      <inertia ixx="1.0E-09" ixy="0.0" ixz="0.0" iyy="1.0E-09" iyz="0.0" izz="1.0E-09" />
    </inertial>
    <visual>
      <origin xyz="0.015 -0.004 0" rpy="0 0 0" />
      <geometry>
        <sphere radius="0.002" />
      </geometry>
      <material name="">
        <color rgba="1 0 0 1" />
      </material>
    </visual>
    <collision>
      <origin xyz="0 0 0" rpy="0 0 0" />
      <geometry>
        <sphere radius="0.002" />
      </geometry>
    </collision>
  </link>

  <joint name="l_f_joint4_tip" type="fixed">
    <origin xyz="0.02 0 0" rpy="0 0 0" />
    <parent link="l_f_link4_4" />
    <child link="l_f_link4_tip" />
  </joint>

  <link name="l_f_link5_tip">
    <inertial>
      <origin xyz="0 0 0.005" rpy="0 0 0" />
      <mass value="0.001" />
      <inertia ixx="1.0E-09" ixy="0.0" ixz="0.0" iyy="1.0E-09" iyz="0.0" izz="1.0E-09" />
    </inertial>
    <visual>
      <origin xyz="0.015 -0.004 0" rpy="0 0 0" />
      <geometry>
        <sphere radius="0.002" />
      </geometry>
      <material name="">
        <color rgba="1 0 0 1" />
      </material>
    </visual>
    <collision>
      <origin xyz="0 0 0" rpy="0 0 0" />
      <geometry>
        <sphere radius="0.002" />
      </geometry>
    </collision>
  </link>

  <joint name="l_f_joint5_tip" type="fixed">
    <origin xyz="0.02 0 0" rpy="0 0 0" />
    <parent link="l_f_link5_4" />
    <child link="l_f_link5_tip" />
  </joint>
</robot>
